Workbook

Sheet README
A1: 第13期 内部監査（SCMG）母集団・サンプルリスト ― インシデント恒久対応策の運用監査
A2: 作成日：2026/10/13 出典：【SCMG】インシデント管理シート（https://docs.google.com/spreadsheets/d/17NCGQXYveGqJzdmtqglT3GNkxo_pvol41Q8K_QYao9Q/ ）の2026/06/05時点データ
A4: ■ シート構成
A5: ・母集団_2024-2026：SCMGの2024〜2026年発見インシデント32件（他Gで起票1件を含む）。G1承認・G4完了確認・ステータスは数式で自動判定。サンプル区分と確認観点は監査人の事前判断（手入力）。
A6: ・集計：年別×レベル別、原因分類、記録状況（すべて母集団シートを参照する数式）。
A7: ・再発パターン：2020〜2026年の全件から同型事象を整理。恒久対応が機能しているかを判断する材料。
A8: ・事例6件_調書：監査調書テンプレ（templates/02）を6事例分に展開。黄色セルを監査当日に記入。
A9: ・事前依頼リスト：監査実施通知（●）に添付して、現物を準備してもらうための一覧。
A10: ・全件_2020-2026：参照用の全82件（主要列のみ）。
A12: ■ 判定記号（数式）
A13: G1 承認：○＝承認者と承認日あり／△＝承認者のみで承認日なし／×＝承認形跡なし
A14: G4 完了確認：○＝対応完了日あり／×＝未記入（事務局の完了確認日列はSCMGシートに無いため、対応完了日で代替）
... A23: ・2023年9月以前は原因分類が「有／無」（システム起因の有無）で記録されており、現行分類（業務起因_作業起因 等）とは比較できない。

Sheet 母集団_2024-2026
A1: No | B1: ユニークID | C1: サービス | D1: 発生日 | E1: 発見日 | F1: 発見年 | G1: 課題タイトル | H1: 原因分類 | I1: レベル | J1: 影響範囲 | K1: 会計影響 | L1: 恒久対応策（抜粋） | M1: 恒久対応PL | N1: 恒久対応承認者 | O1: 恒久対応承認日 | P1: 完了予定日 | Q1: 対応完了日 | R1: 恒久対応の有効性 | S1: G1 承認 | T1: G4 完了確認 | U1: ステータス | V1: 再発タグ | W1: サンプル区分 | X1: 監査での確認観点 | Y1: 監査結果(○△×－) | Z1: 確認した証憑・メモ
A2: 52 | B2: SCMG-52 | C2: airCloset | D2: 2024/01/28 | E2: 2024/01/29 | F2: 2024 | G2: Disney_梱包シールの貼り間違え | H2: 業務起因_作業起因 | I2: 1 | J2: 1人 | K2: なし | L2: シールの台紙に、ミッキーとミニーの表記をすることで、 シールを貼る時に、勘違いに気付けるようにする。 （シール自体は変更しない。貼ってある台紙を工夫する） | M2: tony | N2: icchi | S2: =IF(AND(N2<>"",O2<>""),"○",IF(N2<>"","△","×")) -> △ | T2: =IF(Q2<>"","○","×") -> × | U2: =IF(L2="","対策未記載",IF(Q2<>"","完了（有効性未評価）",IF(AND(P2<>"",P2<TODAY()),"期限超過",IF(O2="","承認日なし","対応中（期限未設定）")))) -> 承認日なし | V2: 梱包ミス | W2: 参考
A3: 53 | B3: SCMG-53 | C3: airCloset | D3: 2024/02/05 | E3: 2024/02/08 | F3: 2024 | G3: コンセプトブックの同梱漏れ | H3: 業務起因_ルール不足 | I3: 3 | J3: 285名 (2/5~2/7出荷の新規発送のお客様) (185円*285名=52,725円) | K3: なし | L3: 同梱物の進行を口頭で進めるのではなく、スプレットシートを用いて、確認項目を関係者全員が確認できるようにする。 同梱を一人で行うとミスに気づけないため、確認者をSCM2名にするフローに変更する。 （同梱依頼シートの作成、専用スラックの作成） https://docs.google.com/spreadsheets/d/1a5EkyEtkdVyCQgKU0mNGjKJEJWIwNwRvG97QP31FSrc/edit#gid=0&range=B5 | M3: tony | N3: ash | O3: 45338 | P3: 45338 | Q3: 45338 | S3: =IF(AND(N3<>"",O3<>""),"○",IF(N3<>"","△","×")) -> ○ | T3: =IF(Q3<>"","○","×") -> ○ | U3: =IF(L3="","対策未記載",IF(Q3<>"","完了（有効性未評価）",IF(AND(P3<>"",P3<TODAY()),"期限超過",IF(O3="","承認日なし","対応中（期限未設定）")))) -> 完了（有効性未評価） | V3: 同梱物運用（指示・期日） | W3: ★事例④ | X3: 「同梱依頼シート＋確認者SCM2名」のフローが現在も運用されているか。直近の同梱依頼シートの記入実績を確認。
A4: 54 | B4: SCMG-54 | C4: airCloset | D4: 2024/02/29 | E4: 2024/03/01 | F4: 2024 | G4: 事後稟議 | H4: 業務起因_ルール不足 | I4: 3 | J4: 事後稟議 | L4: 現場契約書や発注書が出てきた段階で反社チェックを申請しているが、新たにコンタクトを取った時点で申請することを周知徹底する。 また仲介であっても基本的にはNDA及び反社チェックは基本的には行うルールとして敷く。 その管理はWBSやアタックリストなどで反社チェックとNDAの有無のチェックリストは入れる | M4: takk | N4: ash | O4: 45357 | P4: 45357 | S4: =IF(AND(N4<>"",O4<>""),"○",IF(N4<>"","△","×")) -> ○ | T4: =IF(Q4<>"","○","×") -> × | U4: =IF(L4="","対策未記載",IF(Q4<>"","完了（有効性未評価）",IF(AND(P4<>"",P4<TODAY()),"期限超過",IF(O4="","承認日なし","対応中（期限未設定）")))) -> 期限超過 | V4: 事後稟議・契約管理 | W4: ★事例③ | X4: 「新規コンタクト時点で反社チェック申請」「仲介でもNDA・反社チェック実施」のルールと、WBS/アタックリストのチェック項目の現物を確認。2023(#44)・2025(#64)と繰り返し発生。
A5: 55 | B5: SCMG-55 | C5: airCloset | D5: 2024/02/15 | E5: 2024/03/21 | F5: 2024 | G5: DisneyのC品が二次流通業者へ引き渡された | H5: 業務起因_ルール不足 | I5: 3 | K5: なし | L5: Bridge側でC品登録した際に、2次流通NGとわかる表示をできるようにする → 上記情報をairCloset / Disneyそれぞれのシステムで管理して、その情報をBridgeへ連携できるようにする 人と人の認識のすり合わせではなく、 SCMGの担当者が認知していなくても、倉庫現場ではブランドの確認など必要なく、表示が出たもののみ2次流通業者への引き渡しをしないようにする | M5: Jedi | N5: ash | O5: 45385 | P5: 45473 | S5: =IF(AND(N5<>"",O5<>""),"○",IF(N5<>"","△","×")) -> ○ | T5: =IF(Q5<>"","○","×") -> × | U5: =IF(L5="","対策未記載",IF(Q5<>"","完了（有効性未評価）",IF(AND(P5<>"",P5<TODAY()),"期限超過",IF(O5="","承認日なし","対応中（期限未設定）")))) -> 期限超過 | V5: 期限超過（システム対策） | W5: ★事例⑥ | X5: Bridgeでの「2次流通NG表示」が実装されたか画面で確認。完了予定2024/6/30に対し完了日未記入（2年以上経過）。未実装なら現行の運用代替策を確認。
A6: 56 | B6: SCMG-56 | C6: airCloset | D6: 2024/03/09 | E6: 2024/03/29 | F6: 2024 | G6: 同梱個数連携のシステム異常 （アパガード歯磨き粉） | H6: システム起因_仕様考慮漏れ | I6: 他Gで起票 | J6: 496人 | K6: なし | L6: PGDへ移管でクローズ システムの改修になる。 https://air-closet.backlog.jp/view/AIRCLOSET-69679 | M6: tony | S6: =IF(AND(N6<>"",O6<>""),"○",IF(N6<>"","△","×")) -> × | T6: =IF(Q6<>"","○","×") -> × | U6: =IF(L6="","対策未記載",IF(Q6<>"","完了（有効性未評価）",IF(AND(P6<>"",P6<TODAY()),"期限超過",IF(O6="","承認日なし","対応中（期限未設定）")))) -> 承認日なし | V6: システム（同梱連携） | W6: 参考
A7: 57 | B7: SCMG-57 | C7: airCloset | D7: 2024/06/05 | E7: 2024/06/07 | F7: 2024 | G7: 配送テレコ | H7: 業務起因_作業起因 | I7: 1 | J7: 1名 | K7: 返送費と発送費 合わせて3,000円程度 | L7: 暫定同様 | M7: tony | N7: icchi | S7: =IF(AND(N7<>"",O7<>""),"○",IF(N7<>"","△","×")) -> △ | T7: =IF(Q7<>"","○","×") -> × | U7: =IF(L7="","対策未記載",IF(Q7<>"","完了（有効性未評価）",IF(AND(P7<>"",P7<TODAY()),"期限超過",IF(O7="","承認日なし","対応中（期限未設定）")))) -> 承認日なし | V7: 配送テレコ | W7: 参考
A8: 58 | B8: SCMG-58 | C8: airCloset | D8: 2024/07/23 | E8: 2024/07/25 | F8: 2024 | G8: 同梱設定にバグの顕在化 | H8: システム起因_仕様考慮漏れ | I8: 1 | J8: 1名 | K8: なし(対応コストのみ) | L8: システムバグを改修する | S8: =IF(AND(N8<>"",O8<>""),"○",IF(N8<>"","△","×")) -> × | T8: =IF(Q8<>"","○","×") -> × | U8: =IF(L8="","対策未記載",IF(Q8<>"","完了（有効性未評価）",IF(AND(P8<>"",P8<TODAY()),"期限超過",IF(O8="","承認日なし","対応中（期限未設定）")))) -> 承認日なし | V8: システム（同梱連携） | W8: 参考
A9: 59 | B9: SCMG-59 | C9: airCloset | D9: 2024/08/06 | E9: 2024/08/06 | F9: 2024 | G9: オーク物流での停電による作業停止 | H9: 業務起因_作業起因 | I9: 3 | J9: 66名 | K9: なし | L9: ①Wi-Fiのバックアップを用意する。（固定IPをもつインターネットの冗長化） ②業務基本契約書第２１条（事故処理）に即して、OAK物流倉庫の電源強化等の対応を依頼（OAK物流様側の対応）…取扱い電圧の許容度の拡大と設備の改善・新調等の対応（経過報告を依頼し、承諾済み） ③出荷前検品は、通常のオペレーションと確保する労働時間を切り分け、イレギュラーが起きても、出荷前検品に影響が出づらい状況を作る(8月末契約改定予定） ①・③については8月末を期日に調整中。 ②についてはOAK様から週次で進捗を確認中。（方針確定から工事完了までに時間を要する想定のため、分けて管理する方針。） | N9: ash | O9: 45525 | P9: 45535 | S9: =IF(AND(N9<>"",O9<>""),"○",IF(N9<>"","△","×")) -> ○ | T9: =IF(Q9<>"","○","×") -> × | U9: =IF(L9="","対策未記載",IF(Q9<>"","完了（有効性未評価）",IF(AND(P9<>"",P9<TODAY()),"期限超過",IF(O9="","承認日なし","対応中（期限未設定）")))) -> 期限超過 | V9: 期限超過（システム対策） | W9: ★事例⑥ | X9: Wi-Fi冗長化（固定IP回線のバックアップ）・OAK物流の電源強化・出荷前検品の工数切り分け（8月末契約改定）の実施有無。完了予定2024/8/31に対し完了日未記入。
A10: 60 | B10: SCMG-60 | C10: airCloset | D10: 2024/09/11 | E10: 2024/09/07 | F10: 2024 | G10: ハルメク同梱品のテレコ | H10: 業務起因_作業起因 | I10: 1 | J10: 9名 | K10: なし | N10: icchi | S10: =IF(AND(N10<>"",O10<>""),"○",IF(N10<>"","△","×")) -> △ | T10: =IF(Q10<>"","○","×") -> × | U10: =IF(L10="","対策未記載",IF(Q10<>"","完了（有効性未評価）",IF(AND(P10<>"",P10<TODAY()),"期限超過",IF(O10="","承認日なし","対応中（期限未設定）")))) -> 対策未記載 | V10: 同梱物運用（指示・期日） | W10: 参考 | X10: 恒久対応策空欄。同梱カード旧版の廃棄漏れ→#61・#68と同じ同梱物運用の弱さ。
A11: 61 | B11: SCMG-61 | C11: airCloset | D11: 2024/12/22 | E11: 2024/12/22 | F11: 2024 | G11: JTB同梱カードの在庫切れ | H11: 業務起因_作業起因 | I11: 3 | J11: 300名 22日：16名 23日：59名 24日〜220名程度の予測 | K11: なし | L11: ①現場在庫の棚卸しのルール化。 全ての同梱品を1に1回全てカウントする業務を実施する。(1ヶ月4,000円/円程度のコスト) ②同梱データのシステム改善 現在は、同梱数のデータが実態とズレため、データでの管理ができていない。 データを現実と合わる改善をし、データ上でも管理できるようにする。 | M11: tony | N11: mash | S11: =IF(AND(N11<>"",O11<>""),"○",IF(N11<>"","△","×")) -> △ | T11: =IF(Q11<>"","○","×") -> × | U11: =IF(L11="","対策未記載",IF(Q11<>"","完了（有効性未評価）",IF(AND(P11<>"",P11<TODAY()),"期限超過",IF(O11="","承認日なし","対応中（期限未設定）")))) -> 承認日なし | V11: 同梱物在庫管理 | W11: ★事例① | X11: 恒久対応①「全同梱品の月次棚卸しルール化」②「同梱数データのシステム改善」が実施されているか。棚卸し記録（直近月）・OAK物流との作業合意/費用の現物を確認。#62で「未実行」が判明した事例の本体。
A12: 62 | B12: SCMG-62 | C12: airCloset | D12: 2025/01/07 | E12: 2025/01/07 | F12: 2025 | G12: インシデント#61 の恒久対応が実行できていなかった | H12: 業務起因_作業起因 | I12: 3 | J12: 90名 | K12: なし | L12: カウントを実施し、向こう一か月は同様の事象は発生しないことを確認ずみ。 一か月内に、NO,61で想定していた対応が実施できるようにする。 具体的にはカウント作業の作業手順と、必要な作用工数（金銭コストを含む）を明確にしオーク物流様に作業の実行するための対応余力を確保することを依頼する。もし、実行できない場合には想定作業を実行する人員を、エアークローゼット側で調達する。 | N12: mash | S12: =IF(AND(N12<>"",O12<>""),"○",IF(N12<>"","△","×")) -> △ | T12: =IF(Q12<>"","○","×") -> × | U12: =IF(L12="","対策未記載",IF(Q12<>"","完了（有効性未評価）",IF(AND(P12<>"",P12<TODAY()),"期限超過",IF(O12="","承認日なし","対応中（期限未設定）")))) -> 承認日なし | V12: 同梱物在庫管理 | W12: ★事例① | X12: #61の恒久対応が未実行で再発した案件。「一か月内にNo.61の対応を実施」の結果（棚卸し手順書・工数合意・代替人員）を確認。承認日・完了予定日・完了日いずれも未記入。
A13: 63 | B13: SCMG-63 | C13: airCloset | D13: 2025/02/17 | E13: 2025/02/17 | F13: 2025 | G13: 伝票の乗り移り | H13: 業務起因_作業起因 | I13: 3 | J13: 2名 | K13: なし | L13: 暫定対応を同じ | M13: tony | N13: mash | S13: =IF(AND(N13<>"",O13<>""),"○",IF(N13<>"","△","×")) -> △ | T13: =IF(Q13<>"","○","×") -> × | U13: =IF(L13="","対策未記載",IF(Q13<>"","完了（有効性未評価）",IF(AND(P13<>"",P13<TODAY()),"期限超過",IF(O13="","承認日なし","対応中（期限未設定）")))) -> 承認日なし | V13: 伝票トラブル | W13: Lv3全件
A14: 64 | B14: SCMG-64 | C14: airCloset | D14: 2025/02/19 | E14: 2025/02/19 | F14: 2025 | G14: 事後稟議_流山ボイラーの保守契約 | H14: 業務起因_ルール不足 | I14: 3 | J14: 0名 | K14: 0名 | L14: 春日部移転に際して、同一事象の発生する可能性がある。そのため ①契約関係の一元管理ファイルを作成し、契約書を全てを管理する ②契約書の担当者をつけ、全てに関して把握でき、ヌケモレがないようにする | M14: tony | N14: mash | S14: =IF(AND(N14<>"",O14<>""),"○",IF(N14<>"","△","×")) -> △ | T14: =IF(Q14<>"","○","×") -> × | U14: =IF(L14="","対策未記載",IF(Q14<>"","完了（有効性未評価）",IF(AND(P14<>"",P14<TODAY()),"期限超過",IF(O14="","承認日なし","対応中（期限未設定）")))) -> 承認日なし | V14: 事後稟議・契約管理 | W14: ★事例③ | X14: 「契約関係の一元管理ファイル」「契約書担当者の設置」が実現しているか。春日部移転で同一事象が起きていないか、管理ファイルの現物で確認。
A15: 65 | B15: SCMG-65 | C15: その他 | D15: 2025/04/11 | E15: 2025/04/11 | F15: 2025 | G15: vivit様への請求漏れ | H15: 業務起因_作業起因 | I15: 2 | J15: 57,000円の請求漏れ | K15: 57,000円の請求漏れ | L15: 請求書シート作業時にはコピーを作成し、そちらで作業を行う | N15: icchi | S15: =IF(AND(N15<>"",O15<>""),"○",IF(N15<>"","△","×")) -> △ | T15: =IF(Q15<>"","○","×") -> × | U15: =IF(L15="","対策未記載",IF(Q15<>"","完了（有効性未評価）",IF(AND(P15<>"",P15<TODAY()),"期限超過",IF(O15="","承認日なし","対応中（期限未設定）")))) -> 承認日なし | V15: 委託先請求 | W15: 参考
A16: 66 | B16: SCMG-66 | C16: airCloset | D16: 2025/05/19 | E16: 2025/05/20 | F16: 2025 | G16: エコセールの BASEへの伝票番号の記載エラー | H16: 業務起因_作業起因 | I16: 3 | J16: 71名 | K16: なし | L16: ブリッジのDLデータが正しく出るように修正を行う | M16: tony | S16: =IF(AND(N16<>"",O16<>""),"○",IF(N16<>"","△","×")) -> × | T16: =IF(Q16<>"","○","×") -> × | U16: =IF(L16="","対策未記載",IF(Q16<>"","完了（有効性未評価）",IF(AND(P16<>"",P16<TODAY()),"期限超過",IF(O16="","承認日なし","対応中（期限未設定）")))) -> 承認日なし | V16: 手作業データ処理 | W16: Lv3全件 | X16: 恒久対応「BridgeのDLデータ修正」の実装有無（承認者・承認日なし）。
A17: 67 | B17: SCMG-67 | C17: その他 | D17: 2025/05/24 | E17: 2025/05/24 | F17: 2025 | G17: ドレス 発送遅延 | H17: 業務起因_作業起因 | I17: 1 | J17: 1名 | K17: なし | L17: システム改修。 倉庫側での手動キャンセルがなくなるように、上位側のシステムを改修する。 | M17: tukky | N17: icchi | S17: =IF(AND(N17<>"",O17<>""),"○",IF(N17<>"","△","×")) -> △ | T17: =IF(Q17<>"","○","×") -> × | U17: =IF(L17="","対策未記載",IF(Q17<>"","完了（有効性未評価）",IF(AND(P17<>"",P17<TODAY()),"期限超過",IF(O17="","承認日なし","対応中（期限未設定）")))) -> 承認日なし | V17: 手作業データ処理 | W17: 参考
A18: 68 | B18: SCMG-68 | C18: airCloset | D18: 2025/07/17 | E18: 2025/08/04 | F18: 2025 | G18: 友達紹介DMの発送停止ミス | H18: 業務起因_作業起因 | I18: 3 | J18: ac-divとの相違：2,853名（7/17-8/4までに送るべきでないのに送ってしまったお客様の数） 期間外の発送：771名（7/29-8/4に送付した、無効… | K18: なし | L18: 設定期日に気づける仕組みを自動化する／担当者だけに属人化させない 同梱依頼のフローは、依頼ファイル入力⇨スラック連絡で始まる。 https://docs.google.com/spreadsheets/d/1a5EkyEtkdVyCQgKU0mNGjKJEJWIwNwRvG97QP31FSrc/edit?gid=0#gid=0&range=B2 この依頼設定が入力された段階で、 期日アラートを組む（担当者不在でも対応できるようにチームに共有される場所で実施する） →このアラートは現場にも共有される場所で行われ、エアクロメンバーがアクションを起こさなくても計画通りの実行（停止）ができる状況をゴールとする。（まずはここまでを直ちに実行する） →さらに進んで、ブリッジ・コンソール上での計画・統御が… | M18: tony | N18: mash | S18: =IF(AND(N18<>"",O18<>""),"○",IF(N18<>"","△","×")) -> △ | T18: =IF(Q18<>"","○","×") -> × | U18: =IF(L18="","対策未記載",IF(Q18<>"","完了（有効性未評価）",IF(AND(P18<>"",P18<TODAY()),"期限超過",IF(O18="","承認日なし","対応中（期限未設定）")))) -> 承認日なし | V18: 同梱物運用（指示・期日） | W18: ★事例④ | X18: #53のフローは動いていたが期日を見逃した案件。恒久対応「期日アラートの自動化／属人化排除」が同梱依頼シートに実装され、現場共有の場で通知されているかを現物で確認。承認日なし。
A19: 69 | B19: SCMG-69 | C19: airCloset | D19: 2025/09/01 | E19: 2025/09/03 | F19: 2025 | G19: ヤマト発送 ビジネスメンバーズでの日時変更ができない | H19: 業務起因_作業起因 | I19: 3 | J19: 1,154名 | K19: なし | M19: tony | N19: ash | S19: =IF(AND(N19<>"",O19<>""),"○",IF(N19<>"","△","×")) -> △ | T19: =IF(Q19<>"","○","×") -> × | U19: =IF(L19="","対策未記載",IF(Q19<>"","完了（有効性未評価）",IF(AND(P19<>"",P19<TODAY()),"期限超過",IF(O19="","承認日なし","対応中（期限未設定）")))) -> 対策未記載 | V19: 配送業者・外部起因 | W19: Lv3全件 | X19: Lv3・1,154名影響だが恒久対応策空欄（原因不明のまま）。クローズ判断の根拠を確認。
A20: 70 | B20: SCMG-70 | C20: airCloset | D20: 2025/11/03 | E20: 2025/11/03 | F20: 2025 | G20: 日本郵便発送 11/3発送予定分が、発送できてません。 | H20: 業務起因_ルール不足 | I20: 3 | J20: 109名 対象者への出荷が一日遅延します。 | N20: ash | S20: =IF(AND(N20<>"",O20<>""),"○",IF(N20<>"","△","×")) -> △ | T20: =IF(Q20<>"","○","×") -> × | U20: =IF(L20="","対策未記載",IF(Q20<>"","完了（有効性未評価）",IF(AND(P20<>"",P20<TODAY()),"期限超過",IF(O20="","承認日なし","対応中（期限未設定）")))) -> 対策未記載 | V20: 配送業者・外部起因 | W20: Lv3全件 | X20: 外部（ピックゴー）起因だが恒久対応策空欄。委託先への再発防止要請・補償の記録を確認。
A21: 71 | B21: SCMG-71 | C21: airCloset | D21: 2025/11/06 | E21: 2025/11/06 | F21: 2025 | G21: 佐川急便配送・返送 配送遅延 | I21: 3 | J21: 現状、佐川様から連絡あった人数 258名 （11月5日発送6日着のお客様） 状況が落ち着くまで増加の可能性あり | N21: ash | S21: =IF(AND(N21<>"",O21<>""),"○",IF(N21<>"","△","×")) -> △ | T21: =IF(Q21<>"","○","×") -> × | U21: =IF(L21="","対策未記載",IF(Q21<>"","完了（有効性未評価）",IF(AND(P21<>"",P21<TODAY()),"期限超過",IF(O21="","承認日なし","対応中（期限未設定）")))) -> 対策未記載 | V21: 配送業者・外部起因 | W21: Lv3全件 | X21: 原因分類・恒久対応策ともに空欄。外部起因でも分類と「対応不要」の判断記録は必要。
A22: 72 | B22: SCMG-72 | C22: airCloset | D22: 2025/10/31 | E22: 2025/11/04 | F22: 2025 | G22: 在庫が存在しない商品を販売在庫として反映させてしまったショップ切替ミス | H22: 業務起因_作業起因 | I22: 1 | J22: 販売予定お客様6名 | K22: なし | N22: icchi | S22: =IF(AND(N22<>"",O22<>""),"○",IF(N22<>"","△","×")) -> △ | T22: =IF(Q22<>"","○","×") -> × | U22: =IF(L22="","対策未記載",IF(Q22<>"","完了（有効性未評価）",IF(AND(P22<>"",P22<TODAY()),"期限超過",IF(O22="","承認日なし","対応中（期限未設定）")))) -> 対策未記載 | V22: 在庫・ショップ切替 | W22: 参考
A23: 73 | B23: SCMG-73 | C23: airCloset | D23: 2025/11/22 | E23: 2025/11/22 | F23: 2025 | G23: 202511度のエコセ用福袋に関して中身のテレコが発生 | H23: 業務起因_作業起因 | I23: 3 | J23: テレコ対象個品53点中 お客様に発送済みで返金対応 20件 発送前で、欠品発送orキャンセル 14件 | N23: ash | S23: =IF(AND(N23<>"",O23<>""),"○",IF(N23<>"","△","×")) -> △ | T23: =IF(Q23<>"","○","×") -> × | U23: =IF(L23="","対策未記載",IF(Q23<>"","完了（有効性未評価）",IF(AND(P23<>"",P23<TODAY()),"期限超過",IF(O23="","承認日なし","対応中（期限未設定）")))) -> 対策未記載 | V23: 在庫・ショップ切替 | W23: Lv3全件 | X23: Lv3だが恒久対応策が空欄。福袋作成指示シートの数式更新漏れ＝手作業依存。再発防止策の有無を確認。
A24: 74 | B24: SCMG-74 | C24: airCloset | D24: 2025/11/29 | E24: 2025/11/28 | F24: 2025 | G24: 11/29発送分の佐川急便集荷が行われない | H24: 配送業者起因 | I24: 3 | J24: 11/29日佐川急便で発送予定だったお客様 962名 | N24: ash | S24: =IF(AND(N24<>"",O24<>""),"○",IF(N24<>"","△","×")) -> △ | T24: =IF(Q24<>"","○","×") -> × | U24: =IF(L24="","対策未記載",IF(Q24<>"","完了（有効性未評価）",IF(AND(P24<>"",P24<TODAY()),"期限超過",IF(O24="","承認日なし","対応中（期限未設定）")))) -> 対策未記載 | V24: 配送業者・外部起因 | W24: Lv3全件 | X24: 配送業者起因。繁忙期の集荷停止に備えた代替配送の検討があるか確認。
A25: 75 | B25: SCMG-75 | C25: Mall | D25: 2025/12/18 | E25: 2026/01/24 | F25: 2026 | G25: 伝票同梱による、個人情報流出 | H25: 業務起因_作業起因 | I25: 3 | J25: 2名(個人情報を流出させてしまったお客様と、個人情報を受け取ったお客様) | K25: なし | L25: 現場側の恒久対応に関しては、 ① 返却荷受後のお客様送り状は即時廃棄とし、廃棄時に当日の返却点数と送り状枚数の一致確認を行う運用へ変更→ 物理的に送り状が工程内に残らない構造へ移行し、混入リスクを排除します。 ② B品対応時の情報管理は、付箋・メモ用紙等の個別管理を廃止し、すべてメンテナンスチェックシートのメモ欄へ一元集約→ 情報管理媒体を統一し、工程内情報の分散・逸脱を防止します。 SCM、mallからの対応としては、お客様管理シートのアップデートと周知徹底、を行い、現場で個人情報が保管される状態を是正する。 | M25: Don | N25: ash | O25: 46050 | S25: =IF(AND(N25<>"",O25<>""),"○",IF(N25<>"","△","×")) -> ○ | T25: =IF(Q25<>"","○","×") -> × | U25: =IF(L25="","対策未記載",IF(Q25<>"","完了（有効性未評価）",IF(AND(P25<>"",P25<TODAY()),"期限超過",IF(O25="","承認日なし","対応中（期限未設定）")))) -> 対応中（期限未設定） | V25: 個人情報（伝票混入） | W25: ★事例⑤ | X25: 「返却荷受後の送り状即時廃棄＋当日返却点数と送り状枚数の一致確認」「B品メモのメンテチェックシート一元化」がOAK物流の手順に反映されているか。改訂手順書・一致確認記録を確認。完了予定日・完了日なし。
A26: 76 | B26: SCMG-76 | C26: Mall | D26: 2026/02/28 | E26: 2026/02/28 | F26: 2026 | G26: 出荷締め漏れにより、お客様に出荷完了メールが飛ばない | H26: 業務起因_作業起因 | I26: 3 | J26: 60件 | K26: なし | L26: 出荷締め完了後にSCMに連絡を送っていただく SCMも18:00までに連絡がない場合は確認を行う 現状bridgeを使用していない為、システム的にステータス変更後に通知を飛ばすのは困難な為、現状手動・能動的な確認対応で再発防止に努めている段階です。 以下、オーク様側からいただいた再発防止対応になります。 ■運用ルール ① 毎日17時にアラームを設定 ② アラームは任意で解除しない ③ アラーム作動時は他作業を中断し、締め作業を最優先とする ④ 締め完了後、必ずSlackへ完了報告を行う | N26: ash | S26: =IF(AND(N26<>"",O26<>""),"○",IF(N26<>"","△","×")) -> △ | T26: =IF(Q26<>"","○","×") -> × | U26: =IF(L26="","対策未記載",IF(Q26<>"","完了（有効性未評価）",IF(AND(P26<>"",P26<TODAY()),"期限超過",IF(O26="","承認日なし","対応中（期限未設定）")))) -> 承認日なし | V26: 出荷締め漏れ | W26: ★事例② | X26: OAK物流側ルール（17時アラーム／締め完了後のSlack報告）とSCM側の18時確認が運用されているか。Slackの完了報告履歴（直近1〜2週間）を確認。2週間後に#77で同型再発。
A27: 77 | B27: SCMG-77 | C27: その他 | D27: 2026/03/16 | E27: 2026/03/17 | F27: 2026 | G27: 【東京ソワール様】案件において出荷締め漏れが発生し、お客様に出荷完了メールが飛ばない | H27: 業務起因_作業起因 | I27: 2 | J27: 24件 | K27: なし | L27: 出荷締めの実施有無を日次で確認するSlack通知を導入する。 あわせて、出荷締め完了時には当該通知スレッドへ完了報告を行う運用とすることで、対応状況の可視化および対応漏れの防止を図る。 | N27: icchi | S27: =IF(AND(N27<>"",O27<>""),"○",IF(N27<>"","△","×")) -> △ | T27: =IF(Q27<>"","○","×") -> × | U27: =IF(L27="","対策未記載",IF(Q27<>"","完了（有効性未評価）",IF(AND(P27<>"",P27<TODAY()),"期限超過",IF(O27="","承認日なし","対応中（期限未設定）")))) -> 承認日なし | V27: 出荷締め漏れ | W27: ★事例② | X27: 「出荷締め実施有無を日次確認するSlack通知」が実装・稼働しているか。通知の実物とスレッドの完了報告実績を確認。2021(#9)・2023(#39,#40)・2026(#76)と5回目の同型事象。
A28: 78 | B28: SCMG-78 | C28: その他 | D28: 2026/04/07 | E28: 2026/4/8,4/9 | F28: 2026 | G28: 【vivit】案件において、チャーターに積載する荷物を誤ってヤマト出荷として対応及び、荷物積載漏れを起こしてしまった | H28: 業務起因_作業起因 | I28: 2 | J28: チャーター1案件 | N28: icchi | S28: =IF(AND(N28<>"",O28<>""),"○",IF(N28<>"","△","×")) -> △ | T28: =IF(Q28<>"","○","×") -> × | U28: =IF(L28="","対策未記載",IF(Q28<>"","完了（有効性未評価）",IF(AND(P28<>"",P28<TODAY()),"期限超過",IF(O28="","承認日なし","対応中（期限未設定）")))) -> 対策未記載 | V28: 委託先作業ミス | W28: 参考 | X28: 委託先（TOPOS）作業ミスだが恒久対応策空欄・「厳重注意」のみ。
A29: 79 | B29: SCMG-79 | C29: airCloset | D29: 2026/05/18 | E29: 2026/05/19 | F29: 2026 | G29: 5/18出荷分ヤマト様への出荷データ(配送番号)送付漏れてしまった。 | H29: 業務起因_作業起因 | I29: 3 | J29: 5/18ヤマト運輸出荷分全て 276件 | L29: googleアカウントの設定直し。 事象が発生した際の共有依頼。 | N29: ash | S29: =IF(AND(N29<>"",O29<>""),"○",IF(N29<>"","△","×")) -> △ | T29: =IF(Q29<>"","○","×") -> × | U29: =IF(L29="","対策未記載",IF(Q29<>"","完了（有効性未評価）",IF(AND(P29<>"",P29<TODAY()),"期限超過",IF(O29="","承認日なし","対応中（期限未設定）")))) -> 承認日なし | V29: アカウント管理 | W29: Lv3全件 | X29: 倉庫で使用するGoogleアカウントの二段階認証でログイン不可→共有アカウントの疑い。固定設問No.16（アカウント共同利用）と合わせて確認。恒久対応が「設定直し・共有依頼」のみで人依存。
A30: 80 | B30: SCMG-80 | C30: Mall | D30: 2026/05/21 | E30: 2026/05/22 | F30: 2026 | G30: Mallの商品が数点紛失状態になっている | H30: 業務起因_作業起因 | I30: 3 | J30: 商品6点 | K30: 下代合計:512,529円 | N30: ash | S30: =IF(AND(N30<>"",O30<>""),"○",IF(N30<>"","△","×")) -> △ | T30: =IF(Q30<>"","○","×") -> × | U30: =IF(L30="","対策未記載",IF(Q30<>"","完了（有効性未評価）",IF(AND(P30<>"",P30<TODAY()),"期限超過",IF(O30="","承認日なし","対応中（期限未設定）")))) -> 対策未記載 | V30: 在庫・紛失 | W30: Lv3全件 | X30: Lv3・下代51万円の紛失。恒久対応策空欄・調査中のまま。捜索結果と在庫差異の棚卸しルールを確認。
A31: 81 | B31: SCMG-81 | C31: airCloset | D31: 2026/05/28 | E31: 2026/05/28 | F31: 2026 | G31: スポットレンタルで商品のテレコ発送してしまった | H31: 業務起因_作業起因 | I31: 1 | J31: 1件 | N31: icchi | S31: =IF(AND(N31<>"",O31<>""),"○",IF(N31<>"","△","×")) -> △ | T31: =IF(Q31<>"","○","×") -> × | U31: =IF(L31="","対策未記載",IF(Q31<>"","完了（有効性未評価）",IF(AND(P31<>"",P31<TODAY()),"期限超過",IF(O31="","承認日なし","対応中（期限未設定）")))) -> 対策未記載 | V31: 配送テレコ | W31: 参考
A32: 82 | B32: SCMG-82 | C32: その他 | D32: 2026/06/03 | E32: 2026/06/03 | F32: 2026 | G32: vivit様への請求漏れ | H32: システム起因_システムバグ | I32: 1 | J32: 84,912円の請求漏れ | K32: 84,912円の請求漏れ | N32: icchi | S32: =IF(AND(N32<>"",O32<>""),"○",IF(N32<>"","△","×")) -> △ | T32: =IF(Q32<>"","○","×") -> × | U32: =IF(L32="","対策未記載",IF(Q32<>"","完了（有効性未評価）",IF(AND(P32<>"",P32<TODAY()),"期限超過",IF(O32="","承認日なし","対応中（期限未設定）")))) -> 対策未記載 | V32: 委託先請求 | W32: 参考
A33: 83 | B33: SCMG-83 | C33: その他 | D33: 2026/06/05 | E33: 2026/06/05 | F33: 2026 | G33: 配送テレコ | H33: 業務起因_作業起因 | I33: 1 | J33: 2件 | N33: icchi | S33: =IF(AND(N33<>"",O33<>""),"○",IF(N33<>"","△","×")) -> △ | T33: =IF(Q33<>"","○","×") -> × | U33: =IF(L33="","対策未記載",IF(Q33<>"","完了（有効性未評価）",IF(AND(P33<>"",P33<TODAY()),"期限超過",IF(O33="","承認日なし","対応中（期限未設定）")))) -> 対策未記載 | V33: 配送テレコ | W33: 参考

Sheet 集計
A1: ① 年別×レベル別（発見年ベース）
A2: 発見年 | B2: レベル1 | C2: レベル2 | D2: レベル3 | E2: 他Gで起票 | F2: 合計
A3: 2024 | B3: =COUNTIFS('母集団_2024-2026'!$F$2:$F$33,$A3,'母集団_2024-2026'!$I$2:$I$33,"1") -> 4 | C3: =COUNTIFS('母集団_2024-2026'!$F$2:$F$33,$A3,'母集団_2024-2026'!$I$2:$I$33,"2") -> 0 | D3: =COUNTIFS('母集団_2024-2026'!$F$2:$F$33,$A3,'母集団_2024-2026'!$I$2:$I$33,"3") -> 5 | E3: =COUNTIFS('母集団_2024-2026'!$F$2:$F$33,$A3,'母集団_2024-2026'!$I$2:$I$33,"他Gで起票") -> 1 | F3: =COUNTIF('母集団_2024-2026'!$F$2:$F$33,$A3) -> 10
A4: 2025 | B4: =COUNTIFS('母集団_2024-2026'!$F$2:$F$33,$A4,'母集団_2024-2026'!$I$2:$I$33,"1") -> 2 | C4: =COUNTIFS('母集団_2024-2026'!$F$2:$F$33,$A4,'母集団_2024-2026'!$I$2:$I$33,"2") -> 1 | D4: =COUNTIFS('母集団_2024-2026'!$F$2:$F$33,$A4,'母集団_2024-2026'!$I$2:$I$33,"3") -> 10 | E4: =COUNTIFS('母集団_2024-2026'!$F$2:$F$33,$A4,'母集団_2024-2026'!$I$2:$I$33,"他Gで起票") -> 0 | F4: =COUNTIF('母集団_2024-2026'!$F$2:$F$33,$A4) -> 13
A5: 2026 | B5: =COUNTIFS('母集団_2024-2026'!$F$2:$F$33,$A5,'母集団_2024-2026'!$I$2:$I$33,"1") -> 3 | C5: =COUNTIFS('母集団_2024-2026'!$F$2:$F$33,$A5,'母集団_2024-2026'!$I$2:$I$33,"2") -> 2 | D5: =COUNTIFS('母集団_2024-2026'!$F$2:$F$33,$A5,'母集団_2024-2026'!$I$2:$I$33,"3") -> 4 | E5: =COUNTIFS('母集団_2024-2026'!$F$2:$F$33,$A5,'母集団_2024-2026'!$I$2:$I$33,"他Gで起票") -> 0 | F5: =COUNTIF('母集団_2024-2026'!$F$2:$F$33,$A5) -> 9
A6: 合計 | B6: =SUM(B3:B5) -> 9 | C6: =SUM(C3:C5) -> 3 | D6: =SUM(D3:D5) -> 19 | E6: =SUM(E3:E5) -> 1 | F6: =SUM(F3:F5) -> 32
A7: ※2026年は6月5日まで（シート最終更新日）。
A9: ② 原因分類×レベル（2024-2026）
A10: 原因分類 | B10: レベル1 | C10: レベル2 | D10: レベル3 | E10: 他Gで起票 | F10: 合計
A11: 業務起因_作業起因 | B11: =COUNTIFS('母集団_2024-2026'!$H$2:$H$33,$A11,'母集団_2024-2026'!$I$2:$I$33,"1") -> 7 | C11: =COUNTIFS('母集団_2024-2026'!$H$2:$H$33,$A11,'母集団_2024-2026'!$I$2:$I$33,"2") -> 3 | D11: =COUNTIFS('母集団_2024-2026'!$H$2:$H$33,$A11,'母集団_2024-2026'!$I$2:$I$33,"3") -> 12 | E11: =COUNTIFS('母集団_2024-2026'!$H$2:$H$33,$A11,'母集団_2024-2026'!$I$2:$I$33,"他Gで起票") -> 0 | F11: =COUNTIF('母集団_2024-2026'!$H$2:$H$33,$A11) -> 22
A12: 業務起因_ルール不足 | B12: =COUNTIFS('母集団_2024-2026'!$H$2:$H$33,$A12,'母集団_2024-2026'!$I$2:$I$33,"1") -> 0 | C12: =COUNTIFS('母集団_2024-2026'!$H$2:$H$33,$A12,'母集団_2024-2026'!$I$2:$I$33,"2") -> 0 | D12: =COUNTIFS('母集団_2024-2026'!$H$2:$H$33,$A12,'母集団_2024-2026'!$I$2:$I$33,"3") -> 5 | E12: =COUNTIFS('母集団_2024-2026'!$H$2:$H$33,$A12,'母集団_2024-2026'!$I$2:$I$33,"他Gで起票") -> 0 | F12: =COUNTIF('母集団_2024-2026'!$H$2:$H$33,$A12) -> 5
A13: システム起因_仕様考慮漏れ | B13: =COUNTIFS('母集団_2024-2026'!$H$2:$H$33,$A13,'母集団_2024-2026'!$I$2:$I$33,"1") -> 1 | C13: =COUNTIFS('母集団_2024-2026'!$H$2:$H$33,$A13,'母集団_2024-2026'!$I$2:$I$33,"2") -> 0 | D13: =COUNTIFS('母集団_2024-2026'!$H$2:$H$33,$A13,'母集団_2024-2026'!$I$2:$I$33,"3") -> 0 | E13: =COUNTIFS('母集団_2024-2026'!$H$2:$H$33,$A13,'母集団_2024-2026'!$I$2:$I$33,"他Gで起票") -> 1 | F13: =COUNTIF('母集団_2024-2026'!$H$2:$H$33,$A13) -> 2
A14: システム起因_システムバグ | B14: =COUNTIFS('母集団_2024-2026'!$H$2:$H$33,$A14,'母集団_2024-2026'!$I$2:$I$33,"1") -> 1 | C14: =COUNTIFS('母集団_2024-2026'!$H$2:$H$33,$A14,'母集団_2024-2026'!$I$2:$I$33,"2") -> 0 | D14: =COUNTIFS('母集団_2024-2026'!$H$2:$H$33,$A14,'母集団_2024-2026'!$I$2:$I$33,"3") -> 0 | E14: =COUNTIFS('母集団_2024-2026'!$H$2:$H$33,$A14,'母集団_2024-2026'!$I$2:$I$33,"他Gで起票") -> 0 | F14: =COUNTIF('母集団_2024-2026'!$H$2:$H$33,$A14) -> 1
A15: 配送業者起因 | B15: =COUNTIFS('母集団_2024-2026'!$H$2:$H$33,$A15,'母集団_2024-2026'!$I$2:$I$33,"1") -> 0 | C15: =COUNTIFS('母集団_2024-2026'!$H$2:$H$33,$A15,'母集団_2024-2026'!$I$2:$I$33,"2") -> 0 | D15: =COUNTIFS('母集団_2024-2026'!$H$2:$H$33,$A15,'母集団_2024-2026'!$I$2:$I$33,"3") -> 1 | E15: =COUNTIFS('母集団_2024-2026'!$H$2:$H$33,$A15,'母集団_2024-2026'!$I$2:$I$33,"他Gで起票") -> 0 | F15: =COUNTIF('母集団_2024-2026'!$H$2:$H$33,$A15) -> 1
A16: （空欄） | B16: =COUNTIFS('母集団_2024-2026'!$H$2:$H$33,"",'母集団_2024-2026'!$I$2:$I$33,"1") -> 0 | C16: =COUNTIFS('母集団_2024-2026'!$H$2:$H$33,"",'母集団_2024-2026'!$I$2:$I$33,"2") -> 0 | D16: =COUNTIFS('母集団_2024-2026'!$H$2:$H$33,"",'母集団_2024-2026'!$I$2:$I$33,"3") -> 1 | E16: =COUNTIFS('母集団_2024-2026'!$H$2:$H$33,"",'母集団_2024-2026'!$I$2:$I$33,"他Gで起票") -> 0 | F16: =COUNTIF('母集団_2024-2026'!$H$2:$H$33,"") -> 1
A17: 合計 | B17: =SUM(B11:B16) -> 9 | C17: =SUM(C11:C16) -> 3 | D17: =SUM(D11:D16) -> 19 | E17: =SUM(E11:E16) -> 1 | F17: =SUM(F11:F16) -> 32
A18: 業務起因の比率（レベル3） | D18: =(D11+D12)/D17 -> 0.89473684
A21: ③ 恒久対応の記録状況
A22: 指標 | B22: 全体（件） | C22: 全体（率） | D22: レベル3（件） | E22: レベル3（率）
A23: 母集団件数 | B23: =COUNTA('母集団_2024-2026'!$B$2:$B$33) -> 32 | D23: =COUNTIF('母集団_2024-2026'!$I$2:$I$33,"3") -> 19
A24: 恒久対応策の記入 | B24: =COUNTIF('母集団_2024-2026'!$L$2:$L$33,"<>") -> 20 | C24: =B24/$B$23 -> 0.625 | D24: =COUNTIFS('母集団_2024-2026'!$I$2:$I$33,"3",'母集団_2024-2026'!$L$2:$L$33,"<>") -> 13 | E24: =D24/$D$23 -> 0.68421053
A25: 恒久対応承認者の記入 | B25: =COUNTIF('母集団_2024-2026'!$N$2:$N$33,"<>") -> 29 | C25: =B25/$B$23 -> 0.90625 | D25: =COUNTIFS('母集団_2024-2026'!$I$2:$I$33,"3",'母集団_2024-2026'!$N$2:$N$33,"<>") -> 18 | E25: =D25/$D$23 -> 0.94736842
A26: 恒久対応承認日の記入 | B26: =COUNTIF('母集団_2024-2026'!$O$2:$O$33,"<>") -> 5 | C26: =B26/$B$23 -> 0.15625 | D26: =COUNTIFS('母集団_2024-2026'!$I$2:$I$33,"3",'母集団_2024-2026'!$O$2:$O$33,"<>") -> 5 | E26: =D26/$D$23 -> 0.26315789
A27: 完了予定日の設定 | B27: =COUNTIF('母集団_2024-2026'!$P$2:$P$33,"<>") -> 4 | C27: =B27/$B$23 -> 0.125 | D27: =COUNTIFS('母集団_2024-2026'!$I$2:$I$33,"3",'母集団_2024-2026'!$P$2:$P$33,"<>") -> 4 | E27: =D27/$D$23 -> 0.21052632
A28: 対応完了日の記入 | B28: =COUNTIF('母集団_2024-2026'!$Q$2:$Q$33,"<>") -> 1 | C28: =B28/$B$23 -> 0.03125 | D28: =COUNTIFS('母集団_2024-2026'!$I$2:$I$33,"3",'母集団_2024-2026'!$Q$2:$Q$33,"<>") -> 1 | E28: =D28/$D$23 -> 0.052631579
A29: 有効性の記入 | B29: =COUNTIF('母集団_2024-2026'!$R$2:$R$33,"<>") -> 0 | C29: =B29/$B$23 -> 0 | D29: =COUNTIFS('母集団_2024-2026'!$I$2:$I$33,"3",'母集団_2024-2026'!$R$2:$R$33,"<>") -> 0 | E29: =D29/$D$23 -> 0
A30: 参考：GRG（2024-2026・159件）は恒久対応策93.1%／完了予定日52.8%／対応完了日33.3%／有効性0.0%（GRG監査資料より）
A32: ④ ステータス内訳（レベル3）
A33: ステータス | B33: 件数
A34: 対策未記載 | B34: =COUNTIFS('母集団_2024-2026'!$I$2:$I$33,"3",'母集団_2024-2026'!$U$2:$U$33,$A34) -> 6
A35: 承認日なし | B35: =COUNTIFS('母集団_2024-2026'!$I$2:$I$33,"3",'母集団_2024-2026'!$U$2:$U$33,$A35) -> 8
A36: 期限超過 | B36: =COUNTIFS('母集団_2024-2026'!$I$2:$I$33,"3",'母集団_2024-2026'!$U$2:$U$33,$A36) -> 3
A37: 対応中（期限未設定） | B37: =COUNTIFS('母集団_2024-2026'!$I$2:$I$33,"3",'母集団_2024-2026'!$U$2:$U$33,$A37) -> 1
A38: 完了（有効性未評価） | B38: =COUNTIFS('母集団_2024-2026'!$I$2:$I$33,"3",'母集団_2024-2026'!$U$2:$U$33,$A38) -> 1

Sheet 再発パターン
A1: 再発パターン | B1: 該当インシデント（ユニークID／発見日／レベル） | C1: 掲げられた恒久対応策の変遷 | D1: 監査での論点
A2: 出荷締め漏れ | B2: #9 2021/11 Lv2（Mall）／#39 2023/6 Lv3／#40 2023/6 Lv3／#76 2026/2 Lv3（Mall 60件）／#77 2026/3 Lv2（東京ソワール 24件） | C2: 2021：現場作業員が締め→18時半に管理者確認 ／ 2023：OAK側で担当者を限定・交代制 ／ 2026/2：17時アラーム＋Slack完了報告 ／ 2026/3：日次Slack通知の導入 | D2: 5年間で5回、同じ「人が締めを忘れる」事象。毎回「確認を強化する」運用策で、締め未実施をシステム側で検知する仕組み（通知の自動化）が今回ようやく登場。通知が本当に動いているか現物で確認。
A3: 事後稟議・契約管理 | B3: #44 2023/10 Lv3（不入流解約合意書）／#54 2024/3 Lv3（GLP倉庫 反社チェック・NDA未了）／#64 2025/2 Lv3（流山ボイラー保守契約） | C3: 2023：メールでエビデンス＋カレンダー登録 ／ 2024：新規コンタクト時点で反社申請・WBSにチェック項目 ／ 2025：契約一元管理ファイル＋契約担当者 | D3: 倉庫移転（流山→春日部）など契約が集中する局面で繰り返し発生。「契約一元管理ファイル」の現物と、春日部移転時の契約一覧で運用を確認。固定設問No.10・11と直結。
A4: 同梱物の運用（在庫・指示・期日） | B4: #34 2023/3 Lv3／#47 2023/11 Lv3（資材ショート）／#53 2024/2 Lv3（285名）／#60 2024/9 Lv1／#61 2024/12 Lv3（300名）／#62 2025/1 Lv3（#61の恒久対応未実行）／#68 2025/7 Lv3（2,853名） | C4: 2023：月次棚卸しに現場分も含める ／ 2024/2：同梱依頼シート＋確認者2名 ／ 2024/12：同梱品の月次棚卸しルール化＋同梱データのシステム改善 ／ 2025/7：期日アラート自動化・属人化排除 | D4: #62は「恒久対応が実行されていなかった」こと自体がインシデント。本監査テーマの中核事例。棚卸し・アラートが実装され継続しているかを証憑で確認。
A5: 配送テレコ・伝票トラブル | B5: #11 2021/12 Lv3／#57 2024/6 Lv1／#63 2025/2 Lv3／#81 2026/5 Lv1／#83 2026/6 Lv1／#75 2025/12 Lv3（伝票同梱→個人情報流出） | C5: 多くが「現場への厳重注意」「注意喚起」。#75のみ構造的対策（送り状即時廃棄＋枚数一致確認） | D5: 委託先（OAK物流・TOPOS）の作業ミスが「厳重注意」で終わっていないか。業務基本契約書第21条（事故処理）に基づく委託先側の手順改訂・報告を求めているか。
A6: 委託先・配送業者起因で恒久対応が空欄 | B6: #69 2025/9 Lv3（1,154名）／#70 2025/11 Lv3（109名）／#71 2025/11 Lv3（258名）／#74 2025/11 Lv3（962名）／#78 2026/4 Lv2 | C6: 恒久対応策・承認日ともに空欄が大半 | D6: 外部起因でも「再発防止要請・補償・代替手段」の検討記録は必要。「対応不要」ならその判断と承認を残す運用になっているか。
A7: 手作業データ処理のポカミス | B7: #45 2023/10 Lv1／#66 2025/5 Lv3（71名）／#67 2025/5 Lv1／#72 2025/10 Lv1／#73 2025/11 Lv3（福袋テレコ） | C7: システム改修を恒久対応に掲げるが承認日・完了日なし | D7: PDGへの改修依頼（Backlogチケット）が起票され進んでいるか。改修完了までの暫定運用（チェックリスト等）があるか。
A8: アカウント管理 | B8: #79 2026/5 Lv3（276件：倉庫のGoogleアカウント2段階認証でログイン不可） | C8: 設定直し・事象発生時の共有依頼 | D8: 倉庫で使う共有アカウントの存在。固定設問No.16（アカウント共同利用）の評価に直結。

Sheet 事例6件_調書
A1: 事例 | B1: インシデント | C1: テスト観点 | D1: 確認内容（事前準備した論点） | E1: 確認した証憑（当日記入） | F1: 結果(○△×－) | G1: 発見事項（当日記入）
A2: ① | B2: #61 JTB同梱カードの在庫切れ（2024/12/22 Lv3 300名） #62 #61の恒久対応が実行できていなかった（2025/1/7 Lv3 90名） | C2: G1 承認 | D2: 承認者mash・承認日なし（2件とも）。Lv3の社長承認の形跡（役員会確認欄も空欄）を確認。
C3: G2 実装・運用 | D3: 同梱品の月次棚卸し記録（直近月）、OAK物流との作業合意・費用、同梱数データの改善状況を現物で確認。
C4: G3 有効性・再発 | D4: 2025/1以降に同梱物の在庫切れ・旧版混入が再発していないか。対策が「人がカウントする」のみに留まっていないか。
C5: G4 完了確認 | D5: 完了予定日・対応完了日ともに未記入。クローズ判断の有無。
C6: 総合評価 | D6: ○有効／△一部不備／×不備／－対応中 → 結論（事実→影響→根本原因）と改善の要否
A8: ② | B8: #76 出荷締め漏れ（Mall 2026/2/28 Lv3 60件） #77 出荷締め漏れ（東京ソワール 2026/3/16 Lv2 24件） | C8: G1 承認 | D8: 承認者ash／icchi、承認日なし。
C9: G2 実装・運用 | D9: 17時アラーム＋Slack完了報告（#76）と日次Slack通知（#77）の実物。直近2週間の完了報告実績とSCM側の未報告時フォロー記録。
C10: G3 有効性・再発 | D10: 2021・2023・2026と5回目の同型。通知導入後の再発有無。将来的にbridge/システムで締め未実施を検知できないかの検討状況。
C11: G4 完了確認 | D11: 完了予定日・対応完了日ともに未記入。
C12: 総合評価 | D12: ○有効／△一部不備／×不備／－対応中 → 結論（事実→影響→根本原因）と改善の要否
A14: ③ | B14: #54 事後稟議（GLP倉庫 反社チェック・NDA未了 2024/2 Lv3） #64 事後稟議（流山ボイラー保守契約 2025/2 Lv3） | C14: G1 承認 | D14: #54は承認日2024/3/6あり。#64は承認者mash・承認日なし。
C15: G2 実装・運用 | D15: 契約一元管理ファイルの現物・更新日、契約担当者の設置、WBS/アタックリストの反社・NDAチェック項目。春日部移転に伴う契約の一覧。
C16: G3 有効性・再発 | D16: 2023/10 #44を含め3回目。2026年に新たな事後稟議が発生していないか（ADO側の事後稟議記録とも突合）。
C17: G4 完了確認 | D17: #54は完了予定2024/3/6に対し完了日なし。#64は完了予定・完了日なし。
C18: 総合評価 | D18: ○有効／△一部不備／×不備／－対応中 → 結論（事実→影響→根本原因）と改善の要否
A20: ④ | B20: #53 コンセプトブックの同梱漏れ（2024/2 Lv3 285名） #68 友達紹介DMの発送停止ミス（2025/7 Lv3 2,853名） | C20: G1 承認 | D20: #53は承認ash 2024/2/16。#68は承認者mash・承認日なし。
C21: G2 実装・運用 | D21: 同梱依頼シート（確認者SCM2名）の直近の運用実績。期日アラートの実装（シート上の設定・Slack通知）と現場共有の場。
C22: G3 有効性・再発 | D22: #53の対策は動いていたが#68で期日見落とし＝人依存部分で再発。アラート自動化後の再発有無。
C23: G4 完了確認 | D23: #68は完了予定・完了日なし。
C24: 総合評価 | D24: ○有効／△一部不備／×不備／－対応中 → 結論（事実→影響→根本原因）と改善の要否
A26: ⑤ | B26: #75 伝票同梱による個人情報流出（Mall 2025/12発生・2026/1発見 Lv3 2名） | C26: G1 承認 | D26: 承認ash 2026/1/28あり。Lv3かつ個人情報案件として社長承認・役員会確認の形跡を確認。
C27: G2 実装・運用 | D27: OAK物流の改訂手順書（送り状即時廃棄・当日返却点数と送り状枚数の一致確認）、メンテチェックシートのメモ欄一元化、お客様管理シートの更新。
C28: G3 有効性・再発 | D28: 個人情報流出の再発有無。出荷時に検知できない構造（格納後は検品なし）が残っていないか。
C29: G4 完了確認 | D29: 完了予定日・対応完了日なし。固定設問No.14（個人情報）とも連動。
C30: 総合評価 | D30: ○有効／△一部不備／×不備／－対応中 → 結論（事実→影響→根本原因）と改善の要否
A32: ⑥ | B32: #55 DisneyのC品が二次流通業者へ引き渡し（2024/2 Lv3） #59 オーク物流の停電による作業停止（2024/8 Lv3 66名） | C32: G1 承認 | D32: #55 承認ash 2024/4/3、#59 承認ash 2024/8/21（いずれも承認日あり）。
C33: G2 実装・運用 | D33: #55：Bridgeの2次流通NG表示の画面。#59：Wi-Fi冗長化の実物、OAK物流の電源強化の経過報告、出荷前検品の契約改定。
C34: G3 有効性・再発 | D34: システム対策に依存する案件で、未実装のまま放置されていないか。未実装なら運用代替策の有無。
C35: G4 完了確認 | D35: #55 完了予定2024/6/30、#59 完了予定2024/8/31に対し、いずれも完了日未記入（2年超の期限超過）。
C36: 総合評価 | D36: ○有効／△一部不備／×不備／－対応中 → 結論（事実→影響→根本原因）と改善の要否

Sheet 事前依頼リスト
A1: # | B1: 関連事例 | C1: 準備いただきたい現物（既存物でOK・新規作成不要） | D1: 想定の形 | E1: 備考
A2: 1 | B2: ① | C2: 同梱品の月次棚卸しの記録（直近月分）とOAK物流との作業合意（工数・費用） | D2: スプレッドシート／メール／Slack | E2: #61・#62の恒久対応
A3: 2 | B3: ①④ | C3: 同梱依頼シートの最新版（確認者2名の運用実績、期日アラートの設定） | D3: スプレッドシート本体・Slack通知 | E3: #53・#68の恒久対応
A4: 3 | B4: ② | C4: 出荷締め完了のSlack報告スレッド（直近2週間）と日次Slack通知の設定画面 | D4: Slackチャンネルを画面共有 | E4: #76・#77の恒久対応
A5: 4 | B5: ③ | C5: 契約一元管理ファイル（契約担当者名・更新日がわかるもの） | D5: スプレッドシート | E5: #64の恒久対応。春日部移転関連契約を含む
A6: 5 | B6: ③ | C6: WBS／アタックリストの反社チェック・NDAチェック項目 | D6: スプレッドシート | E6: #54の恒久対応
A7: 6 | B7: ⑤ | C7: OAK物流の改訂手順書（返却荷受後の送り状即時廃棄・枚数一致確認）と一致確認の記録 | D7: 手順書・チェック記録 | E7: #75の恒久対応
A8: 7 | B8: ⑥ | C8: Bridgeの2次流通NG表示の画面（または未実装の場合の現行運用） | D8: 画面共有 | E8: #55の恒久対応
A9: 8 | B9: ⑥ | C9: Wi-Fi冗長化の状況、OAK物流の電源強化の経過報告 | D9: メール・写真等 | E9: #59の恒久対応
A10: 9 | B10: － | C10: レベル3で恒久対応策が空欄の6件（#69,70,71,73,74,80）について、対応不要と判断した場合はその経緯 | D10: 口頭でも可 | E10: 記録運用の確認
A11: 10 | B11: － | C11: 倉庫で使用しているGoogleアカウントの一覧と利用者（共有の有無） | D11: 口頭でも可 | E11: #79・固定設問No.16
A12: 11 | B12: － | C12: 2026年6月以降に発生したインシデントの有無（未起票分があれば概要） | D12: 口頭でも可 | E12: 固定設問No.17

Sheet 全件_2020-2026
A1: No | B1: ユニークID | C1: 発生日 | D1: 発見日 | E1: 課題タイトル | F1: 原因分類 | G1: レベル | H1: 影響範囲 | I1: 恒久対応策（抜粋） | J1: 恒久対応承認者 | K1: 恒久対応承認日 | L1: 完了予定日 | M1: 対応完了日 | N1: 有効性
A2: 1 | B2: SCMG-1 | C2: 2020/11/10 | D2: 2020/11/10 | E2: エアータッチがセブンイレブンで全ユーザーが使用不可 | F2: 無 | G2: 3 | H2: 事案発生時から、返却でセブンを利用しようとした全ユーザー | I2: 障害発生時の補償についての覚書を結ぶ 12/2 ヤマトと接触 覚書を結ぶ＆障害報告書をもらう合意 12/16 覚書ドラフトを作成、管理部提出 ヤマト繁忙期のため、締結は年明けになりそう 年明け、ヤマト側からの返答なし 引き続き対応中（1/25） 4/5 覚書、経緯書送ってもらい押印確認中 4/12 押印後送付済 | J2: ash | K2: 44167 | L2: 44286 | M2: 44316
A3: 2 | B3: SCMG-2 | C3: 2020/11/27 | D3: 2020/11/30 | E3: 佐川集荷依頼失敗 | F3: 有 | G3: 3 | H3: 27-30の集荷依頼対応者 | I3: チェッカーを2段階にした ※当初レベル2インシデントとして起票 | J3: ash | K3: 44286 | L3: 44286 | M3: 44286
A4: 3 | B4: SCMG-3 | D4: 2021/05/10 | E4: ささげバグ | F4: 有 | G4: 2 | H4: 4000〜10000ピースほど選定に上がらず１シーズン機会損失した | I4: リファクタ改修部分を修正してリリース 対応コミット: https://github.com/air-closet/cella-api/pull/205/files | J4: icchi | K4: 44356 | L4: 44336 | M4: 44356
A5: 4 | B5: SCMG-4 | C5: 2021/09/25 | D5: 2021/09/26 | E5: 佐川集荷依頼失敗 | F5: 有 | G5: 2 | H5: 24人 | I5: 毎日バッチをリリースしてキャッシュを毎日解放する開発をする | J5: icchi | K5: 44469 | L5: 44499 | M5: 44487
A6: 5 | B6: SCMG-5 | C6: 2021/10/12 | D6: 2021/10/12 | E6: スタイリストマイページが見えない | F6: 有 | G6: 2 | I6: PDGで対応 | J6: icchi
A7: 6 | B7: SCMG-6 | C7: 2021/10/13 | D7: 2021/10/13 | E7: 本来出荷できる在庫があるのに選定画面に上がってこない | H7: 確認中 | I7: インシデントではないことをイッチーさんと確認
A8: 7 | B8: SCMG-7 | C8: 2021/10/13 | D8: 2021/10/13 | E8: 本来出荷できる在庫があるのに選定画面に上がってこない | H8: 55SKU 280着使用せずにgo_to_aCなどの対応をしていた | I8: インシデントではないことをイッチーさんと確認
A9: 8 | B9: SCMG-8 | C9: 2021/10/19 | D9: 2021/10/19 | E9: NGタグ登録ができない（WEB・アプリ） | F9: 有 | G9: 3 | H9: 2021-10-18 19:00頃 〜 2021-10-19 18:30の期間中に、 アイテムのBad感想を入力しようと… | I9: PDGで対応 | J9: ash | K9: 44496 | L9: 44592 | M9: 44592
A10: 9 | B10: SCMG-9 | C10: 2021/11/12 | D10: 2021/11/15 | E10: 出荷締め漏れ | F10: 有 | G10: 2 | H10: 【概要】 【人数 or 件数】 11/12出荷のmall全てのオーダー 25件 | I10: エアクロやフィッティングと同じ運用にする 作業終了し出庫後に現場作業員が締め作業を行い、また毎日18時半に管理者が締め作業を完了しているかも確認する 運用定例のトラブル管理シートにてオークさんとも確認ずみ | J10: icchi | K10: 44529 | L10: 44529 | M10: 44529
A11: 10 | B11: SCMG-10 | C11: 2021/11/27 | D11: 2021/12/08 | E11: aCでは過去アイテム購入処理されているのに、 Cella上ではSOLD表記されている | F11: 有 | G11: 2 | H11: 【概要】 【人数 or 件数】 このフローに乗って、返送アイテムを手元に残した状態で購入したお客様 7名 https:/… | I11: CSとの会話 send_back_date以降、returned_date以前に購入したお客様の中で、 手元に残したままの状態で「現品購入」と勘違いして購入されたお客様は7名 CSの感覚としては、初動にしては少ないと思っている | J11: icchi | K11: 44578 | L11: 44578 | M11: 44578
A12: 11 | B12: SCMG-11 | C12: 2021/12/14 | D12: 2021/12/15 | E12: FCで発送荷物を翌日分と当日分を取り違えて発送遅延 （１日） | F12: 無 | G12: 3 | H12: 【概要】 母数は先該当の62件と思われる 【人数 or 件数】 最大62名、1件問い合わせあり | I12: オークさんと相談し提示 ・ピック後の集積場所を分ける ・出荷ラインを分けて、当日分が終わったことをシステムで確認してから翌日分を出荷するようにする | J12: ash | K12: 44553 | L12: 44553 | M12: 44553
A13: 12 | B13: SCMG-12 | C13: 2021/12/15 | D13: 2021/12/16 | E13: 伝票番号重複 | F13: 有 | G13: 2 | H13: 【概要】 【人数 or 件数】 48名 | I13: 引当実行中に再度ボタン押されても、現在実行中のため受け付けない処理を追加しました | J13: icchi | K13: 44553 | L13: 44550 | M13: 44550
A14: 13 | B14: SCMG-13 | C14: 2021/12/17 | D14: 2021/12/19 | E14: 過去アイテム購入の連携が成功しない | F14: 有 | G14: 3 | H14: 【概要】【人数 or 件数】 12/16 14:00:00 ~ 12/17 13:59:59に過去アイテム購入を実施した… | I14: 根本原因解決と、発生後の検知できる体制構築 ・1件落ちると全部落ちるという道連れで他の連携も出荷指示の対象にならないという事象が起きないようにシステム修正済み（差分で出荷指示する） ・デリバリープロバイダーID自体をゼロにするのをやめて、無料会員が有料会員になるときにリセットする方向でシステム改修依頼予定（1月案件） | J14: ash | K14: 44553 | L14: 44592 | M14: 44592
A15: 14 | B15: SCMG-14 | C15: 2021/11/27 | D15: 2021/12/16 | E15: スタイリスト指名画面 次回要望画面に遷移できない | H15: 【概要】 【人数 or 件数】
A16: 15 | B16: SCMG-15 | C16: 2021/12/20 | D16: 2021/12/22 | E16: AC DBデータ修正ミス | F16: 無 | G16: 3 | H16: 172件 | I16: 手動対応で急ぎやる案件としては、誰もができるレベルではないので、大元の連携が落ちる原因の排除を優先しました。 そもそもの出荷指示連携後に同梱物の在庫をチェックするというプロセスを是正 | J16: ash | K16: 44553 | L16: 44553 | M16: 44553
A17: 17 | B17: SCMG-17 | C17: 2022/02/12 | D17: 2022/02/15 | E17: 2/12出荷予定分のオーダーが 出荷できていなかった | F17: 無 | G17: 2 | H17: 28名 | I17: 7:00のバッチ連携の失敗時には 別でアラートをあげられるように改修 土曜日(今後は日祝）の場合、 モールのオペレーションを対応できるエンジニアがいないため、billyさんしかわからない状態からオペたんで対応できるように体制を変更（maxさんにお伝え済み） | J17: icchi | K17: 44608
A18: 18 | B18: SCMG-18 | C18: 2022/02/10 | D18: 2022/02/18 | E18: エコセール配送遅延/欠品 | F18: 無 | G18: 3 | H18: 51名 | I18: GOto ACとエコセールを同時にやらない （そもそもSKU被らせない） ＆ エコセールの個別出荷をフィティング分はコアブレインに送ってしまいコアブレインから個配してもらい、受注管理を片方に寄せる ※内製化の目処は夏ごろ | J18: ash | K18: 44647
A19: 19 | B19: SCMG-19 | C19: 2022/02/28 | D19: 2022/02/20 | E19: 何らかのバグで出荷指示が出ない | F19: 有 | G19: 2 | H19: 実際のお届けのお約束範囲を、3、4日から遅れた件数 34件 | I19: 一旦バグらしく部分を修正済み 様子見中、出荷波動により見えなくなってるので再現待ち | J19: icchi | K19: 44628
A20: 20 | B20: SCMG-20 | C20: 2022/03/02 | D20: 2022/03/05 | E20: スキャッチ分の出荷遅延 | F20: 無 | G20: 3 | H20: 58名 | I20: アクセとスキャッチの連携タイミングの固定化の解除 なぜやっているかは現場が通常配送と混じってるとテレコなどの作業ミスを誘発させる可能性があったためだったが、bridgeのピッキングのグループ化の改修で判別できるようにすれあ固定化は解除できる | J20: ash | K20: 44647
A21: 21 | B21: SCMG-21 | C21: 2022/09/01 | D21: 2022/04/19 | E21: 入庫せず滞留していた商品がエアクロの商品が150着春日部で見つかった（8ヶ月間） | F21: 無 | G21: 2 | H21: 150着の商品が8ヶ月使えない | I21: 引越しの事象別での振り分けミスが発端 なので起きえない事象ではある。現状発注残管理を開始してるので現状のフローであれば見つかるはずです。 | J21: icchi | K21: 44670
A22: 22 | B22: SCMG-22 | C22: 2022/04/28 | D22: 2022/04/28 | E22: ささげされておらずシーズンで使えない商品があった | F22: 無 | G22: 2 | H22: 150着の商品が8ヶ月使えない | I22: 現場側の対応 ・ささげを行った作業者がささげを完了したらそのお洋服を棚入れする運用に変更し、 棚入れ在庫エリアに、ささげ完了のお洋服を滞留することをなくすことで、未ささげのお洋服が確実にささげエリアに行き、勘違いで、棚入れがおこなられないようにする。また、これを作業者に周知徹底を行う。 ・毎週月曜日に1wk前のささげが終わっていないSKUリストをエアクロフォワードメンバーからまさきさんへ連絡し、 … | J22: icchi | K22: 44715 | L22: 44715 | M22: 44715
A23: 23 | B23: SCMG-23 | C23: 2022/05/30 | D23: 2022/05/30 | E23: エコセールで多数欠品 | F23: 無 | G23: 3 | H23: 80件以上の一部欠品が起きました | I23: 他社のプラットフォームに出店するが故に手動で在庫計算をする必要があるのでストアーズを卒業すればそもそも発生し得なくなります。 とはいえ、中規模開発を伴うので直近で再度行う場合は以下を実行します。 エアクロ内でいろいろな施策（無限ワンセレ等々）が走っている状況を全て把握していないとできない考慮不足。 ・参照先の在庫データの取得方法をエンジニアにヒアリング（出力方法も特殊） ・在庫に詳しいエンジニアに… | J23: ash | K23: 44715 | L23: 44715 | M23: 45019
A24: 24 | B24: SCMG-24 | C24: 2022/06/02 | D24: 2022/06/02 | E24: 配送予定日を間違った内容で自動出荷確定メールが飛んでいる | F24: 無 | G24: 3 | H24: 75名へのお届け予定日の誤連絡 | I24: 手動で連携する原因の排除 この開発を今月中に実施、完了予定です。 開発完了までは手動連携時にはチェック項目に出荷日だけでなくお届け予定日も追加、また二名で実施し相互チェックを行います。 ※アクセを含むオーダーとスキャッチを指定しているオーダーをまとめて特定の時間連携するをやめます。梱包時のミスや作業優先順序を揃えるためにやってましたが別方法で解決 | J24: ash | K24: 44715 | L24: 44715 | M24: 45019
A25: 25 | B25: SCMG-25 | C25: 2022/06/02 | D25: 2022/06/02 | E25: エコセール出荷：二重配送 | F25: 無 | G25: 2 | H25: 16名のお客様 | I25: ①作業フロー整備する 担当：Tony Due:6/10 ②次回からエコセールから出荷連携担当者は1名とする 担当：Tony Due:6/10 ③次回からエコセールから出荷連携者とは別の1名がストアーズとBridgeの情報が1:1になっているか確認する担当を作る 担当：Tony Due:6/10 | J25: icchi | K25: 44715 | L25: 44722 | M25: 45019
A26: 26 | B26: SCMG-26 | C26: 2022/06/14 | D26: 2022/06/14 | E26: 安全ピンがついた状態の洋服がお客様へ流出 | F26: 無 | G26: 3 | H26: 1名のお客様 | I26: ①お客様FAQの更新（安全ピン使わないでのお願い） ②荷受・CL・検品・リペア・・どの工程でも安全ピンに気づいたタイミングで取り外すOP → いま、この認識がない可能性ある → 基準書（ドキュメント）に落とし込んで展開 ③検品強化 ④スポット外注時、依頼先に重要事項として安全ピン（針）の流出防止を伝える＝基準書の展開 ＜対応状況＞ ①6/22DONE | J26: ash | K26: 44732
A27: 27 | B27: SCMG-27 | C27: 2022/09/23 | D27: 2022/09/30 | E27: Bridge停止による過去アイテム購入連携漏れ | F27: 有 | G27: 3 | H27: 100名 | I27: 1,2の出荷処理の1は通過して2 ※PDG対応 | J27: ash | K27: 44874
A28: 28 | B28: SCMG-28 | D28: 2022/10/10 | E28: fitting出荷上限設定漏れによる出荷遅延 | F28: 無 | G28: 2 | H28: 5名 | I28: 開発によって、デフォルトを曜日に関わらず0にする。 | J28: icchi
A29: 29 | B29: SCMG-29 | C29: 2022/09/06 | D29: 2022/10/13 | E29: 再選定ボタンの押し忘れによる出荷遅延 | F29: 無 | G29: 1 | H29: 2名 | I29: Bridge上でオーダーキャンセルする時に キャンセルと同時に再選定を依頼できる仕様に BridgeとDBの仕様変更を行う | J29: icchi
A30: 30 | B30: SCMG-30 | C30: 2022/04/01 | D30: 2022/11/11 | E30: 枠番割り付けミスによる他社との重複発番 | F30: 有 | G30: 3 | H30: 1164名の追跡情報が正しい情報と違う情報が混同した表示に | I30: 本来動くはずのループ処理を実際に動くように改修※PDG対応 | J30: ash | K30: 45266
A31: 31 | B31: SCMG-31 | C31: 2022/11/18 | D31: 2022/11/18 | E31: ヤマトサービスレベルマスタの更新ミス | F31: 有 | G31: 3 | H31: 700名程度 | I31: 暫定対応がそのまま恒久対応となります。※PDG対応すみ | J31: ash | K31: 45266 | M31: 45019
A32: 32 | B32: SCMG-32 | C32: 2022/12/19 | D32: 2022/12/19 | E32: 佐川集荷のCSVが佐川に送れていない | F32: 有 | G32: 2 | H32: 40名 | I32: 落ちる原因と思われる内部SFTPのバージョンアップデート＆現在フェイタルチャンネルで上がっている通知は過去の落ちた場合の再起動通知（メンションなし）なので実際落ちてるか不明な部分があるので実際に落ちてることが確認できるように通知をするように変更、また現在手動で対応ができないためオペたんが動かない土日でも対応できるようにSCMにS3への接続権限の付与で対応できるようにする | J32: icchi | K32: 45280 | M32: 45019
A33: 33 | B33: SCMG-33 | C33: 2023/01/12 | D33: 2023/01/12 | E33: GOTOACミスで在庫欠品、再選定が数十件発生 | F33: 有 | G33: 2 | H33: 選定53件なので、コスト2万円超で発生 | I33: ショップ切り替えを追加と削除を一回の作業でできるようにシステム改修予定 チケットはもう上がっている状態です | J33: icchi | K33: 44939
A34: 34 | B34: SCMG-34 | C34: 2023/03/14 | D34: 2023/03/15 | E34: スマリ同梱物設定ミス | F34: 無 | G34: 3 | H34: 509名 | I34: 現在、コンソールの同梱設定ページでの対象者の選択プルダウンは、「全会員」がデフォルトとなっており、プルダウンを選択しなくてもデフォルト設定のまま同梱設定が完了できる仕様となっている。 対策として、このプルダウンのデフォルトを解除し、「全会員」または「特定のオーダー」を設定者が都度選択して設定することを必須とする改修を行う。 | J34: ash | K34: 45009 | L34: 45046 | M34: 45046
A35: 35 | B35: SCMG-35 | C35: 2023/03/14 | D35: 2023/03/14 | E35: ピッきんエラーによる33件の出荷遅延と、出荷完了メールでの誤情報の送信 | F35: 有 | G35: 2 | H35: 33件のオーダー | I35: 連携された時点でお届け日が確定するのではなく、出荷実績取得の時点の出荷日を起算としてお届け日が決定する仕様とし、出荷完了メールもそれに倣う形とする。 | J35: icchi | K35: 45008 | L35: 45046
A36: 36 | B36: SCMG-36 | C36: 2023/03/20 | D36: 2023/03/20 | E36: ピッきんエラーによる33件の出荷遅延と、出荷完了メールでの誤情報の送信 | F36: 有 | G36: 2 | H36: 33件のオーダー | I36: 連携された時点でお届け日が確定するのではなく、出荷実績取得の時点の出荷日を起算としてお届け日が決定する仕様とし、出荷完了メールもそれに倣う形とする。 | J36: icchi | K36: 45008 | L36: 45046
A37: 37 | B37: SCMG-37 | C37: 2023/04/03 | D37: 2023/04/03 | E37: オーク物流様へ展開している作業数量の7日前予測が展開されていなかった | F37: 無 | G37: 3 | I37: ①GASの編集権限の引き継ぎ (do→jediへ） ②7日前の日付のAM9:00に7日前予測値をslackでアラート吐き出しをし、両者合意の数値の認識合わせを実施 変更したい場合はそのスラックチャンネル上でオーク様とやりとりをした上で数値変更を実施 | J37: ash | K37: 45068 | L37: 45030
A38: 38 | B38: SCMG-38 | C38: 2023/02/28 | D38: 2023/02/28 | E38: 水質汚濁防止法への対応漏れ（特定施設の申請漏れ） | F38: 無 | G38: 3 | H38: 営業停止処分となった場合は、返却アイテムのクリーニング＝在庫化が間に合わず、選定遅延等のリスクがある | I38: 新規事業およびそれに類するプロジェクトの際は、WBSの中に必ず「関連法令の洗い出し」をタスクとして入れるものとする。 確認先としては、GVAさんや、事業を行う場所の行政（市区町村役所）に問い合わせ。 airCloset Mallに関しては、新規商品を取り扱う際が対象となる。 取引先（仕入先）様との契約書に「当該商品を扱うにあたって関連する法令があるか？ある場合は開示してください」という内容を盛り込… | J38: ash | K38: 45085 | L38: 45090
A39: 39 | B39: SCMG-39 | C39: 2023/06/03 | D39: 2023/06/04 | E39: オーク物流様 出荷締め忘れ | F39: 無 | G39: 3 | H39: 1235名 | I39: オーク様 シフト表を元に担当者を決定しておく、且つ担当者の限定をする。 担当：沢田、平山、有賀の3名の交代制で行うが、基本は社員である沢田or平山が担当 また、あらかじめ社用携帯・平山＋沢田携帯で、締め処理を実行する時間を知らせるアラームを大きめの音量で毎日15:30+17：30にセットしておく。 締め処理担当者はアラームが鳴ったら、たとえ担当者がどんな作業をしていても中断し、すみやかに締め処理の… | J39: ash | K39: 45100 | L39: 45184
A40: 40 | B40: SCMG-40 | C40: 2023/06/04 | D40: 2023/06/05 | E40: オーク物流様 出荷締め忘れ | F40: 無 | G40: 3 | H40: 126件 | I40: オーク様 シフト表を元に担当者を決定しておく、且つ担当者の限定をする。 担当：沢田、平山、有賀の3名の交代制で行うが、基本は社員である沢田or平山が担当 また、あらかじめ社用携帯・平山＋沢田携帯で、締め処理を実行する時間を知らせるアラームを大きめの音量で毎日15:30+17：30にセットしておく。 締め処理担当者はアラームが鳴ったら、たとえ担当者がどんな作業をしていても中断し、すみやかに締め処理の… | J40: ash | K40: 45100 | L40: 45184
...
