Workbook

Sheet README
A1: 第13期 内部監査（経営管理室・ADO）母集団・サンプルリスト ― インシデント恒久対応策の運用監査
A2: 作成日：2026/10/28 出典：【ADO】インシデント管理シート（2026/10/13時点・ADO-1〜33）＋【ADG】インシデント管理シート（2024/7まで・ADG-1〜19）
A3: 監査実施者：森本（監査計画どおり）。経営管理室には内部監査担当（倉石）が所属するため、倉石が起票者・担当者である案件（ADO-2,3,10,12,16,25）は森本がレビューする（監査プログラム 02 §9）。
A5: ■ シート構成
A6: ・母集団_2024-2026：2024〜2026年発見の35件（ADG 2件＋ADO 33件）。G1承認・G4完了確認・ステータスは数式で自動判定。サンプル区分・確認観点は監査人の事前判断。
A7: ・集計：年別×レベル別、原因分類、記録状況（母集団シートを参照する数式）。
A8: ・再発パターン：2020〜2026年の全52件から同型事象を整理。
A9: ・事例6件_調書：監査調書テンプレ（templates/02）を6事例（19件）に展開。黄色セルを監査当日に記入。
A10: ・事前依頼リスト：監査実施通知（●11月）に添付して現物を準備してもらう一覧。
A11: ・ADO②との対応：ADO②（28項目）のうちインシデントと直結する項目の対応表。
A12: ・全件_2020-2026：参照用の全52件（主要列のみ）。
A14: ■ 判定記号（数式）
... A25: ・2027年6月期 内部監査シートのADO②タブの「（前回）監査結果」列は、2024/11の結果ではなく2023年の内容がコピーされたまま（要更新）。

Sheet 母集団_2024-2026
A1: No | B1: ユニークID | C1: 出典 | D1: 発生日 | E1: 発見日 | F1: 発見年 | G1: 課題タイトル | H1: 原因分類 | I1: レベル | J1: 影響範囲 | K1: 会計影響 | L1: 恒久対応策（抜粋） | M1: 恒久対応PL | N1: 恒久対応承認者 | O1: 恒久対応承認日 | P1: 完了予定日 | Q1: 対応完了日 | R1: 恒久対応の有効性（抜粋） | S1: G1 承認 | T1: G4 完了確認 | U1: ステータス | V1: 再発タグ | W1: サンプル区分 | X1: 監査での確認観点 | Y1: 監査結果(○△×－) | Z1: 確認した証憑・メモ
A2: 18 | B2: ADG-18 | C2: ADG | D2: 45307 | E2: 45307 | F2: 2024 | G2: 支払漏れ | H2: 業務起因_作業起因 | I2: 3 | J2: 1名 | K2: 550,000円 | L2: 15日払いの取引先に関するチェックリストが自己チェックになっているため、イレギュラーな対応を実施する場合はダブルチェックを入れていく。 | M2: shuzo | N2: ash | O2: 45307 | P2: 45307 | Q2: 45307 | S2: =IF(AND(N2<>"",O2<>""),"○",IF(N2<>"","△","×")) -> ○ | T2: =IF(Q2<>"","○","×") -> ○ | U2: =IF(L2="","対策未記載",IF(Q2<>"","完了",IF(AND(P2<>"",P2<TODAY()),"期限超過",IF(O2="","承認日なし","対応中")))) -> 完了 | V2: 支払い（漏れ・過重） | W2: Lv3全件 | X2: 業務委託報酬55万円の支払漏れ。恒久対応「イレギュラー時はWチェック」。完了2024/1/16。
A3: 19 | B3: ADG-19 | C3: ADG | D3: 45436 | E3: 45436 | F3: 2024 | G3: 正社員給与の支払い遅延未遂 | H3: 業務起因_ルール不足 | I3: 3 | J3: 特になし | K3: 特になし | L3: 現状、以下の統制行為を実施している。 ①月次決算終了後、口座残高を確認の上資金移動の要否を経理担当が判断している。 ②支払手続実施時に、支払担当が口座残高を確認している。支払手続実施時に、請求書の束と合わせて預金残高を付箋で記載して承認に回すことにする。 仕組みというより、運用の問題だと思いますので徹底を図るのと、カレンダーでの予定を設定し、毎月資金移動するようにします。 | M3: shuzo | N3: ash | O3: 45439 | P3: 45439 | Q3: 45439 | S3: =IF(AND(N3<>"",O3<>""),"○",IF(N3<>"","△","×")) -> ○ | T3: =IF(Q3<>"","○","×") -> ○ | U3: =IF(L3="","対策未記載",IF(Q3<>"","完了",IF(AND(P3<>"",P3<TODAY()),"期限超過",IF(O3="","承認日なし","対応中")))) -> 完了 | V3: 資金繰り・銀行遵守事項 | W3: ★事例② | X3: 2023/6（ADG-14）と同じ給与支払遅延未遂が再発。恒久対応「カレンダーで毎月資金移動」が継続しているか。2024/5/27完了扱い。
A4: 1 | B4: ADO-1 | C4: ADO | D4: 45548 | E4: 45548 | F4: 2024 | G4: 非正規社員給与支払いミス | H4: 業務起因_作業起因 | I4: 3 | J4: 29名 | K4: 5292692.0 | L4: ADO長（shuzo）の振込承認後に、担当者が金融機関のUI上で振込承認されていることを確認する | M4: shuzo | N4: 2024/09/13 | O4: 45548 | P4: 45548 | Q4: 45548 | S4: =IF(AND(N4<>"",O4<>""),"○",IF(N4<>"","△","×")) -> ○ | T4: =IF(Q4<>"","○","×") -> ○ | U4: =IF(L4="","対策未記載",IF(Q4<>"","完了",IF(AND(P4<>"",P4<TODAY()),"期限超過",IF(O4="","承認日なし","対応中")))) -> 完了 | V4: 支払い（漏れ・過重） | W4: Lv3全件 | X4: 非正規給与529万円の支払申請漏れ。恒久対応「振込承認後に金融機関UIで承認を確認」は人の確認。完了2024/9/13。
A5: 2 | B5: ADO-2 | C5: ADO | D5: 確認中ですが、2022年ごろから？ | E5: 45608 | F5: 2024 | G5: モバイルSUICAが個人利用されていた | H5: 業務起因_ルール不足 | I5: 3 | J5: 1名 | K5: 確認中 | L5: 社用モバイルSuicaを利用する場合は、2台持ち（社用携帯＋個人携帯）とする ※1台の端末に複数のモバイルSuica（モバイルPASMO含む）を入れる運用はNGとする | M5: keny | S5: =IF(AND(N5<>"",O5<>""),"○",IF(N5<>"","△","×")) -> × | T5: =IF(Q5<>"","○","×") -> × | U5: =IF(L5="","対策未記載",IF(Q5<>"","完了",IF(AND(P5<>"",P5<TODAY()),"期限超過",IF(O5="","承認日なし","対応中")))) -> 承認日なし | V5: 経費・備品ルール | W5: Lv3全件 | X5: モバイルSuicaの個人利用。恒久対応「2台持ちルール」。承認・期限なし。起票者が倉石のため森本が確認。
A6: 3 | B6: ADO-3 | C6: ADO | D6: 45617 | E6: 45617 | F6: 2024 | G6: 退社時の未施錠が発生した | H6: 業務起因_作業起因 | I6: 2 | J6: なし | K6: なし | M6: keny | S6: =IF(AND(N6<>"",O6<>""),"○",IF(N6<>"","△","×")) -> × | T6: =IF(Q6<>"","○","×") -> × | U6: =IF(L6="","対策未記載",IF(Q6<>"","完了",IF(AND(P6<>"",P6<TODAY()),"期限超過",IF(O6="","承認日なし","対応中")))) -> 対策未記載 | V6: オフィス管理 | W6: 参考 | X6: 退社時の未施錠（Lv2）。恒久対応策空欄。起票者が倉石のため森本が確認。
A7: 4 | B7: ADO-4 | C7: ADO | D7: 45650 | E7: 45650 | F7: 2024 | G7: 候補者送付先ミス | H7: 業務起因_作業起因 | I7: 3 | J7: 1名 | K7: なし | L7: 事象をチーム内で共有し、フルネームを確認することを徹底することを改めて確認しました。 | M7: keny | S7: =IF(AND(N7<>"",O7<>""),"○",IF(N7<>"","△","×")) -> × | T7: =IF(Q7<>"","○","×") -> × | U7: =IF(L7="","対策未記載",IF(Q7<>"","完了",IF(AND(P7<>"",P7<TODAY()),"期限超過",IF(O7="","承認日なし","対応中")))) -> 承認日なし | V7: 個人情報・情報発信 | W7: Lv3全件 | X7: 候補者名の誤記（Lv3）。恒久対応「フルネーム確認の徹底」＝人依存。承認・期限なし。ADO②No.9（個人情報）に関連。
A8: 5 | B8: ADO-5 | C8: ADO | D8: 45713 | E8: 45714 | F8: 2025 | G8: 振込過重払い | H8: 業務起因_ルール不足 | I8: 3 | J8: 3件 | K8: ￥831,449 | L8: 基本は消込後にデータ抽出する。スケジュール的に厳しい場合はデータ抽出後でもデータ上でチェックを実施する（第一チェック者がチェックしたエクセルなどを第二チェック者に共有し、ダブルチェックを行う） | M8: shuzo | N8: shuzo | O8: 45715 | P8: 45715 | Q8: 45715 | S8: =IF(AND(N8<>"",O8<>""),"○",IF(N8<>"","△","×")) -> ○ | T8: =IF(Q8<>"","○","×") -> ○ | U8: =IF(L8="","対策未記載",IF(Q8<>"","完了",IF(AND(P8<>"",P8<TODAY()),"期限超過",IF(O8="","承認日なし","対応中")))) -> 完了 | V8: 支払い（漏れ・過重） | W8: Lv3全件 | X8: 過重払い83万円。恒久対応「消込後にデータ抽出、無理ならExcelを共有してWチェック」。
A9: 6 | B9: ADO-6 | C9: ADO | D9: 45713 | E9: 45714 | F9: 2025 | G9: 振込先相違 | H9: 業務起因_作業起因 | I9: 2 | J9: 2件 | K9: ￥39,600 | L9: イレギュラー支払はフロー内で行うことを徹底する。フロー外は基本的に受けない。フロー外の支払については、GMからshuzoさんへ確認依頼し振込の可否をもらう。 | M9: shuzo | N9: shuzo | O9: 45715 | P9: 45715 | Q9: 45715 | S9: =IF(AND(N9<>"",O9<>""),"○",IF(N9<>"","△","×")) -> ○ | T9: =IF(Q9<>"","○","×") -> ○ | U9: =IF(L9="","対策未記載",IF(Q9<>"","完了",IF(AND(P9<>"",P9<TODAY()),"期限超過",IF(O9="","承認日なし","対応中")))) -> 完了 | V9: 支払い（漏れ・過重） | W9: 参考 | X9: 振込先相違。恒久対応「フロー外のイレギュラー支払は受けない」。完了2025/2/27。
A10: 7 | B10: ADO-7 | C10: ADO | D10: 45741 | E10: 45741 | F10: 2025 | G10: 給与支払いミス（過小）：2025年3月分 | H10: 業務起因_ルール不足 | I10: 3 | J10: 3名 | K10: 70000.0 | L10: 給与台帳と支払金額の一致を確認し、差異原因については上長であるADO長が確認する。 | M10: shuzo | N10: shuzo | O10: 45741 | P10: 45741 | S10: =IF(AND(N10<>"",O10<>""),"○",IF(N10<>"","△","×")) -> ○ | T10: =IF(Q10<>"","○","×") -> × | U10: =IF(L10="","対策未記載",IF(Q10<>"","完了",IF(AND(P10<>"",P10<TODAY()),"期限超過",IF(O10="","承認日なし","対応中")))) -> 期限超過 | V10: 給与計算（SCSK連携） | W10: ★事例④ | X10: カティーサーク受賞者の給与過小。恒久対応「給与台帳と支払金額の一致確認、差異はADO長が確認」が毎月の手順になっているか。完了日なし。
A11: 8 | B11: ADO-8 | C11: ADO | D11: 45810 | E11: 45810 | F11: 2025 | G11: 振込漏れ | H11: 業務起因_作業起因 | I11: 3 | J11: 1件 | K11: 804100.0 | L11: 口座振替、となっているものについても、請求書内容を確認し、月末を経過後に引き落としされていることを確認する時間を作る。 | M11: shuzo | N11: shuzo | O11: 45810 | P11: 45810 | S11: =IF(AND(N11<>"",O11<>""),"○",IF(N11<>"","△","×")) -> ○ | T11: =IF(Q11<>"","○","×") -> × | U11: =IF(L11="","対策未記載",IF(Q11<>"","完了",IF(AND(P11<>"",P11<TODAY()),"期限超過",IF(O11="","承認日なし","対応中")))) -> 期限超過 | V11: 支払い（漏れ・過重） | W11: Lv3全件 | X11: 振込漏れ80万円（口座振替扱いでチェック漏れ）。恒久対応は「確認する時間を作る」。完了日なし。
A12: 9 | B12: ADO-9 | C12: ADO | D12: 45876 | E12: 45876 | F12: 2025 | G12: 振込漏れ | H12: 業務起因_ルール不足 | I12: 1 | J12: 1件 | K12: ￥3,795 | L12: 支払依頼の申請者が実際の業務に関与していなかったために発生している。支払依頼管理表作成時に、担当者への確認をするフローとする。 | M12: shuzo | N12: shuzo | O12: 45879 | P12: 45810 | S12: =IF(AND(N12<>"",O12<>""),"○",IF(N12<>"","△","×")) -> ○ | T12: =IF(Q12<>"","○","×") -> × | U12: =IF(L12="","対策未記載",IF(Q12<>"","完了",IF(AND(P12<>"",P12<TODAY()),"期限超過",IF(O12="","承認日なし","対応中")))) -> 期限超過 | V12: 支払い（漏れ・過重） | W12: 参考 | X12: 振込漏れ（少額）。承認2025/8/10に対し完了日2025/6/2と日付矛盾。
A13: 10 | B13: ADO-10 | C13: ADO | D13: 45852 | E13: 45882 | F13: 2025 | G13: 適時開示漏れ | H13: 業務起因_ルール不足 | I13: 3 | J13: 1件 | K13: なし | L13: ・取締役会の２営業日前に確認時間をスケジュール ・生成AIを用いて、適時開示が必要そうなものがないかを確認（できるかどうか含めてテスト | M13: shuzo | N13: shuzo | O13: 45883 | P13: 45883 | S13: =IF(AND(N13<>"",O13<>""),"○",IF(N13<>"","△","×")) -> ○ | T13: =IF(Q13<>"","○","×") -> × | U13: =IF(L13="","対策未記載",IF(Q13<>"","完了",IF(AND(P13<>"",P13<TODAY()),"期限超過",IF(O13="","承認日なし","対応中")))) -> 期限超過 | V13: 開示・税務 | W13: ★事例⑤ | X13: 借入れの適時開示漏れ（東証指摘）。恒久対応「取締役会2営業日前に確認時間」「生成AIで適時開示要否確認」。カレンダー設定と直近取締役会での確認記録。完了予定2025/8/14に対し完了日なし。
A14: 11 | B14: ADO-11 | C14: ADO | D14: 45870 | E14: 45883 | F14: 2025 | G14: インターン契約更新漏れ | H14: 業務起因_ルール不足 | I14: 3 | J14: 1件 | K14: なし | L14: 契約社員・インターンの管理台帳への記載が漏れないように、入退社チェックリストに当該項目の転記をルール化する。 | M14: shuzo | N14: shuzo | O14: 45889 | P14: 45889 | S14: =IF(AND(N14<>"",O14<>""),"○",IF(N14<>"","△","×")) -> ○ | T14: =IF(Q14<>"","○","×") -> × | U14: =IF(L14="","対策未記載",IF(Q14<>"","完了",IF(AND(P14<>"",P14<TODAY()),"期限超過",IF(O14="","承認日なし","対応中")))) -> 期限超過 | V14: 入退社・労務手続き | W14: ★事例⑥ | X14: インターン契約更新漏れ。恒久対応「入退社チェックリストに契約社員・インターン台帳への転記をルール化」。チェックリストの現物。完了予定2025/8/20に対し完了日なし。
A15: 12 | B15: ADO-12 | C15: ADO | D15: 45754 | E15: 45905 | F15: 2025 | G15: 源泉所得税の申告・納付エラー | H15: 業務起因_作業起因 | I15: 2 | J15: 1件 | K15: 金額不明だが、延滞加算税が課される | M15: shuzo | S15: =IF(AND(N15<>"",O15<>""),"○",IF(N15<>"","△","×")) -> × | T15: =IF(Q15<>"","○","×") -> × | U15: =IF(L15="","対策未記載",IF(Q15<>"","完了",IF(AND(P15<>"",P15<TODAY()),"期限超過",IF(O15="","承認日なし","対応中")))) -> 対策未記載 | V15: 開示・税務 | W15: ★事例⑤ | X15: 源泉所得税の年月誤りで申告未受理・未納（延滞税）。恒久対応策・承認・期限すべて空欄。e-tax申告後の出金記録照合（毎月2本）の運用があるか。
A16: 13 | B16: ADO-13 | C16: ADO | D16: 45912 | E16: 45916 | F16: 2025 | G16: 口座情報登録ミス | H16: 業務起因_作業起因 | I16: 3 | J16: 対象人数：2名 件数；1件 | K16: 2262.0 | L16: ダブルチェックを徹底します。 現状は ・プリントアウトしたものにチェックして欲しい方には印をつける ・slackでお伝えし、可能な限り口頭でも伝える ・ダブルチェックを依頼するためにshuzoさんにお渡しする前にデスクに置き チェック依頼をしていました。 ーーーーーーーーーーーーーーー 今後は入口の部分であるマスター登録のチェックの強化をします。 財務以外のメンバー(経理)にも以下をチェックしてもらってから登録するようにします。 ・マスター番号 ・口座情報 ※外国籍の方の場合は特に登録時のチェックをトリプルチェックにして強化するよう注意します | S16: =IF(AND(N16<>"",O16<>""),"○",IF(N16<>"","△","×")) -> × | T16: =IF(Q16<>"","○","×") -> × | U16: =IF(L16="","対策未記載",IF(Q16<>"","完了",IF(AND(P16<>"",P16<TODAY()),"期限超過",IF(O16="","承認日なし","対応中")))) -> 承認日なし | V16: 支払い（漏れ・過重） | W16: Lv3全件 | X16: 口座登録ミスによる誤送金。恒久対応「マスター登録を経理もチェック、外国籍はトリプルチェック」。承認者・承認日・期限すべて空欄。
A17: 14 | B17: ADO-14 | C17: ADO | D17: 最初に更新できなかった日 | E17: 45957 | F17: 2025 | G17: スタイリストさん契約更新漏れ | H17: 業務起因_ルール不足 | I17: 3 | J17: スタイリスト：8人 | K17: 0.0 | L17: ①最終版をJOBCANに添付することを徹底する。現状では法務依頼は一元化されて管理されているため、チームとして結果を確認している。 ②月次で電子契約が網羅的に台帳に記載されていることを確認するフローを入れる。 ③今回のインシデントと直接は関係無いが、契約書台帳の区分を、①ひな型による契約（自動更新有り）、②ひな型による契約（自動更新無し）、③その他契約、に分けて管理し、②③は契約満了時点でBotでアラートが鳴る仕組みを改めて作る。 | M17: keny | N17: shuzo | S17: =IF(AND(N17<>"",O17<>""),"○",IF(N17<>"","△","×")) -> △ | T17: =IF(Q17<>"","○","×") -> × | U17: =IF(L17="","対策未記載",IF(Q17<>"","完了",IF(AND(P17<>"",P17<TODAY()),"期限超過",IF(O17="","承認日なし","対応中")))) -> 承認日なし | V17: 契約更新・稟議 | W17: ★事例③ | X17: スタイリスト8名の契約更新漏れ。恒久対応（別シートNo14）①最終版をJOBCANに添付の徹底 ②月次で電子契約の台帳網羅性確認 ③台帳区分とBotアラート再構築。承認者shuzoのみで承認日・期限・完了なし。②③の実装有無を確認。
A18: 15 | B18: ADO-15 | C18: ADO | D18: 45975 | E18: 45978 | F18: 2025 | G18: 交通費連携ミス | H18: 業務起因_作業起因 | I18: 3 | J18: 1名 | K18: 7140.0 | L18: ダブルチェックの徹底 現状はkyonkyonさんのみのチェック。今後はshuzoさんにもダブルチェックを依頼します。 その際に、今後は修正一覧表に起票し、ミスが起こりやすい部分を認識することにより、さらに注意して確認をしていきます。 修正一覧表 | M18: makkkiy | S18: =IF(AND(N18<>"",O18<>""),"○",IF(N18<>"","△","×")) -> × | T18: =IF(Q18<>"","○","×") -> × | U18: =IF(L18="","対策未記載",IF(Q18<>"","完了",IF(AND(P18<>"",P18<TODAY()),"期限超過",IF(O18="","承認日なし","対応中")))) -> 承認日なし | V18: 給与計算（SCSK連携） | W18: Lv3全件 | X18: 交通費連携ミス（定期2つのうち1つ）。恒久対応「shuzoにもWチェック依頼・修正一覧表」。承認・期限なし。
A19: 16 | B19: ADO-16 | C19: ADO | D19: 46081 | E19: 46093 | F19: 2026 | G19: 取引先への支払い漏れ | H19: 業務起因_作業起因 | I19: 2 | K19: 83160.0 | L19: ・請求書送信先を法務のMLの設定する ・支払い依頼管理表に追記する | M19: shuzo | N19: shuzo | R19: 半期に一度の請求等でも、支払い依頼管理表に記載されているものについては請求漏れを防げており、本件についても管理表に記載があれば防げたと考えられるため。 | S19: =IF(AND(N19<>"",O19<>""),"○",IF(N19<>"","△","×")) -> △ | T19: =IF(Q19<>"","○","×") -> × | U19: =IF(L19="","対策未記載",IF(Q19<>"","完了",IF(AND(P19<>"",P19<TODAY()),"期限超過",IF(O19="","承認日なし","対応中")))) -> 承認日なし | V19: 支払い（漏れ・過重） | W19: 参考 | X19: 年払い請求の支払漏れ。支払依頼管理表への追記で防げる設計。承認日・期限・完了なし。起票者が倉石のため森本が確認。
A20: 17 | B20: ADO-17 | C20: ADO | D20: 46112 | E20: 46113 | F20: 2026 | G20: 取引先への支払い漏れ | H20: 業務起因_作業起因 | I20: 3 | J20: 1件 | K20: 2237268.0 | L20: 支払管理レポートと支払依頼の件数チェックを行う。 | M20: shuzo | N20: shuzo | O20: 46113 | R20: 支払依頼は各グループから上がってくるため、件数の誤りは発見できる。金額が合っているかは別項目でチェックを行う。 | S20: =IF(AND(N20<>"",O20<>""),"○",IF(N20<>"","△","×")) -> ○ | T20: =IF(Q20<>"","○","×") -> × | U20: =IF(L20="","対策未記載",IF(Q20<>"","完了",IF(AND(P20<>"",P20<TODAY()),"期限超過",IF(O20="","承認日なし","対応中")))) -> 対応中 | V20: 支払い（漏れ・過重） | W20: ★事例① | X20: 日本郵便 224万円の支払漏れ。恒久対応「支払管理レポートと支払依頼の件数チェック」が毎月実施されているか（チェック記録）。freeeの仮申請→差替のステータス運用ルール。
A21: 18 | B21: ADO-18 | C21: ADO | D21: 46136 | E21: 46140 | F21: 2026 | G21: 交通費連携ミス | H21: 業務起因_作業起因 | I21: 3 | J21: 対象人数：1名 | K21: 6350.0 | L21: 今後はすべてSmartHR経由で交通費変更申請をお願いする。 今回のような料金改定により、大人数の変更が発生した際は必ず全員分をまとめて起票する。 | M21: shuzo | N21: shuzo | O21: 46142 | P21: 46142 | Q21: 46142 | S21: =IF(AND(N21<>"",O21<>""),"○",IF(N21<>"","△","×")) -> ○ | T21: =IF(Q21<>"","○","×") -> ○ | U21: =IF(L21="","対策未記載",IF(Q21<>"","完了",IF(AND(P21<>"",P21<TODAY()),"期限超過",IF(O21="","承認日なし","対応中")))) -> 完了 | V21: 給与計算（SCSK連携） | W21: Lv3全件 | X21: 交通費連携ミス（運賃改定）。恒久対応「SmartHR経由に統一」。完了2026/4/30。#15と同型。
A22: 19 | B22: ADO-19 | C22: ADO | D22: 46169 | E22: 46169 | F22: 2026 | G22: 取引先への過重支払 | H22: 業務起因_作業起因 | I22: 3 | J22: 1件 | K22: 1,532,540 円 | L22: ・最終版の請求書と支払依頼書のWチェックを行う。 ・AIチェックを進めるが、それが完成するまではshuzoがトリプルチェックを実施する。 | M22: shuzo | N22: shuzo | O22: 46169 | P22: 46169 | Q22: 46169 | R22: 修正したあとの支払依頼もWチェックを行うことにより、再発の防止が見込める。AIチェックについても今後進めていき、より精度上げる。 | S22: =IF(AND(N22<>"",O22<>""),"○",IF(N22<>"","△","×")) -> ○ | T22: =IF(Q22<>"","○","×") -> ○ | U22: =IF(L22="","対策未記載",IF(Q22<>"","完了",IF(AND(P22<>"",P22<TODAY()),"期限超過",IF(O22="","承認日なし","対応中")))) -> 完了 | V22: 支払い（漏れ・過重） | W22: ★事例① | X22: ヤーマン 153万円の過重払い。「最終版請求書と支払依頼書のWチェック」「AIチェック完成までshuzoのトリプルチェック」の実施記録。完了2026/5/27とされるが同種が#21・#30で再発。
A23: 20 | B23: ADO-20 | C23: ADO | D23: 46137 | E23: 46169 | F23: 2026 | G23: 早出残業手当支払いミス | H23: 業務起因_作業起因 | I23: 3 | J23: 対象人数：2名 うち1名については2ヶ月分の修正が必要であったところ、1名分しか修正できていなかったので追加で対応いたし… | K23: 37,423円→ | L23: ・みなし残業時間を関数に組み込むのではなく、別の列に時間数を入力しておき、関数がその列の値を参照する形式に修正する ・関数に誤りがないかをチェックする | M23: shuzo | N23: shuzo | O23: 46175 | P23: 46176 | R23: みなし残業時間が45時間以外のメンバーはほぼいないので、これでチェックできると考えております。 | S23: =IF(AND(N23<>"",O23<>""),"○",IF(N23<>"","△","×")) -> ○ | T23: =IF(Q23<>"","○","×") -> × | U23: =IF(L23="","対策未記載",IF(Q23<>"","完了",IF(AND(P23<>"",P23<TODAY()),"期限超過",IF(O23="","承認日なし","対応中")))) -> 期限超過 | V23: 給与計算（SCSK連携） | W23: ★事例④ | X23: 早出残業手当の誤支給。恒久対応「みなし残業時間を別列に入力し関数が参照する形式に修正」。修正後のシート現物。完了予定2026/6/3に対し完了日なし。
A24: 21 | B24: ADO-21 | C24: ADO | D24: 46167 | E24: 46189 | F24: 2026 | G24: 取引先への過重支払 | H24: 業務起因_作業起因 | I24: 3 | J24: 1件 | K24: 956,111円 | L24: ①支払依頼の仮申請と差替後の金額に１００万円以上の差異がある場合は差異を自動で検知し、担当者及び上長スラックで連絡を行う。 ②請求書と支払金額のチェックAIの機能に金額の重複を検知を追加する。 | M24: shuzo | N24: shuzo | O24: 46189 | P24: 46189 | Q24: 46189 | R24: ①現状では仮申請と差し替えの金額に乖離があっても上長に承認が入らない状態になっているが、この対策により上長への確認も可能になる。 ②AIチェックの仕組みはすでにできており、精度確認済みのため、対策として有用であると考える。 | S24: =IF(AND(N24<>"",O24<>""),"○",IF(N24<>"","△","×")) -> ○ | T24: =IF(Q24<>"","○","×") -> ○ | U24: =IF(L24="","対策未記載",IF(Q24<>"","完了",IF(AND(P24<>"",P24<TODAY()),"期限超過",IF(O24="","承認日なし","対応中")))) -> 完了 | V24: 支払い（漏れ・過重） | W24: ★事例① | X24: クラスメソッド 96万円の過重払い。恒久対応①「仮申請と差替後の金額差100万円以上を自動検知しSlack通知」②「AIチェックに重複検知を追加」が実装されているか現物（設定・通知例）で確認。完了2026/6/16。
A25: 22 | B25: ADO-22 | C25: ADO | D25: 46127 | E25: 46192 | F25: 2026 | G25: 控除ミス | H25: 業務起因_作業起因 | I25: 3 | J25: 1名 | K25: 9847.0 | L25: イレギュラー支払のチェックリストを作成し、給与がマイナスだった場合を項目の一つとし、毎月チェックする。 チェックリスト：https://docs.google.com/spreadsheets/d/1CPuUv7pODQ_Fy_WBsyozJpzuv5dJxr_zMwXq2KmcZHc/edit?gid=1699869831#gid=1699869831 | M25: shuzo | N25: shuzo | O25: 46192 | P25: 46192 | Q25: 46192 | R25: チェックリストを作成・運用したことで、今回の事象に加え、過去に発生した同様のイレギュラーケースについても確認できる体制を整備しました。 ただ、イレギュラーは他にもあるため、今回のケースはこれで問題無いと考えているが、その他のイレギュラーが発生した際には随時更新する必要がある。 | S25: =IF(AND(N25<>"",O25<>""),"○",IF(N25<>"","△","×")) -> ○ | T25: =IF(Q25<>"","○","×") -> ○ | U25: =IF(L25="","対策未記載",IF(Q25<>"","完了",IF(AND(P25<>"",P25<TODAY()),"期限超過",IF(O25="","承認日なし","対応中")))) -> 完了 | V25: 給与計算（SCSK連携） | W25: ★事例④ | X25: 社保控除で給与マイナス時の立替控除漏れ。恒久対応「イレギュラー支払チェックリストを毎月チェック」。チェックリストの現物と直近月の実施記録。完了2026/6/19。
A26: 23 | B26: ADO-23 | C26: ADO | D26: 46142 | E26: 46191 | F26: 2026 | G26: 銀行との契約上の遵守事項への違反 | H26: 業務起因_ルール不足 | I26: 3 | J26: 現状無し | K26: 現状無し | L26: ・金融機関様との契約書を一度全て洗い出して、他にもこういった条件が無いかを改めて確認する。 ・毎月資金繰りの確認時（現状月に2回実施している）に、当該条件への遵守事項を確認する。 | M26: shuzo | N26: shuzo | O26: 46192 | P26: 46192 | R26: 確認ポイントが明確であれば次回以降発生しないと考えております。 | S26: =IF(AND(N26<>"",O26<>""),"○",IF(N26<>"","△","×")) -> ○ | T26: =IF(Q26<>"","○","×") -> × | U26: =IF(L26="","対策未記載",IF(Q26<>"","完了",IF(AND(P26<>"",P26<TODAY()),"期限超過",IF(O26="","承認日なし","対応中")))) -> 期限超過 | V26: 資金繰り・銀行遵守事項 | W26: ★事例② | X26: みずほ銀行の遵守事項（月末預金残高≧融資残高）違反。恒久対応「金融機関契約の全件洗い出し」「月2回の資金繰り確認時に遵守事項を確認」。洗い出し結果の一覧と確認記録の現物。取締役会・監査役への報告有無。承認2026/6/19、完了日なし。
A27: 24 | B27: ADO-24 | C27: ADO | D27: 45839 | E27: 46225 | F27: 2026 | G27: Meta社広告費の消費税区分誤りに伴う費用計上漏れ | H27: 業務起因_作業起因 | I27: 3 | J27: 約17百万円のコスト計上の増加。 | K27: 同左 | L27: 請求書のAIチェック機能に、以下の確認項目を追加します。 ・会計上の税区分と、請求書に記載された消費税・適格請求書発行事業者登録番号との整合性 ・適格請求書の要件を満たしていない請求書に、仕入税額控除を行う税区分が設定されていないか 不整合が検出された場合は、会計処理を確定する前にエラーまたは警告を表示し、経理担当者が税区分を再確認する運用とします。 | M27: shuzo | N27: shuzo | O27: 46225 | P27: 46234 | R27: インボイスの要件は明確なため、AIチェックの相性は良いと考えています。 | S27: =IF(AND(N27<>"",O27<>""),"○",IF(N27<>"","△","×")) -> ○ | T27: =IF(Q27<>"","○","×") -> × | U27: =IF(L27="","対策未記載",IF(Q27<>"","完了",IF(AND(P27<>"",P27<TODAY()),"期限超過",IF(O27="","承認日なし","対応中")))) -> 期限超過 | V27: 開示・税務 | W27: ★事例⑤ | X27: Meta広告費の消費税区分誤り。恒久対応「請求書AIチェックに税区分・インボイス整合性の確認を追加」。完了予定2026/7/31に対し完了日なし。実装の有無。
A28: 25 | B28: ADO-25 | C28: ADO | D28: 46227 | E28: 46227 | F28: 2026 | G28: ジョブカン承認前に契約締結を実施してしまった | H28: 業務起因_作業起因 | I28: 3 | J28: １社 | K28: なし | S28: =IF(AND(N28<>"",O28<>""),"○",IF(N28<>"","△","×")) -> × | T28: =IF(Q28<>"","○","×") -> × | U28: =IF(L28="","対策未記載",IF(Q28<>"","完了",IF(AND(P28<>"",P28<TODAY()),"期限超過",IF(O28="","承認日なし","対応中")))) -> 対策未記載 | V28: 契約更新・稟議 | W28: ★事例③ | X28: ジョブカン承認前に電子契約へサイン（事後稟議）。暫定対応「運用徹底」のみで恒久対応策・承認・期限すべて空欄。ADO②No.14（決裁ルート）に直結。起票者が倉石のため森本が確認。
A29: 26 | B29: ADO-26 | C29: ADO | D29: 46241 | E29: 46241 | F29: 2026 | G29: 住民税の異動手続きが完了できていなかった | H29: 業務起因_ルール不足 | I29: 2 | J29: 1名 | L29: ・退職WFと産育休WFに「1月1日時点での住民票の住所」を入力してもらう項目を作成する ・異動届を出すタイミングとなる、産育休と退職対応のチェックリストに「1月1日時点での住民票の住所を確認する」という項目を追加する。 | M29: shuzo | N29: shuzo | S29: =IF(AND(N29<>"",O29<>""),"○",IF(N29<>"","△","×")) -> △ | T29: =IF(Q29<>"","○","×") -> × | U29: =IF(L29="","対策未記載",IF(Q29<>"","完了",IF(AND(P29<>"",P29<TODAY()),"期限超過",IF(O29="","承認日なし","対応中")))) -> 承認日なし | V29: 入退社・労務手続き | W29: ★事例⑥ | X29: 住民税異動届の提出先誤り。恒久対応「退職WF・産育休WFに1/1時点住所の項目追加、チェックリスト追加」。WFの現物。承認日・期限・完了なし。
A30: 27 | B30: ADO-27 | C30: ADO | D30: 46238 | E30: 46238 | F30: 2026 | G30: 面接の会議室取り忘れ | H30: 業務起因_作業起因 | I30: 1 | J30: 3名 | L30: 必ずHerpの日程調整ツールから調整を行います。 | M30: shuzo | N30: shuzo | O30: 46252 | P30: 46252 | Q30: 46252 | R30: 会議室が空いていない場合は設定できない仕様です。 | S30: =IF(AND(N30<>"",O30<>""),"○",IF(N30<>"","△","×")) -> ○ | T30: =IF(Q30<>"","○","×") -> ○ | U30: =IF(L30="","対策未記載",IF(Q30<>"","完了",IF(AND(P30<>"",P30<TODAY()),"期限超過",IF(O30="","承認日なし","対応中")))) -> 完了 | V30: 採用オペレーション | W30: 参考 | X30: 面接の会議室取り忘れ。恒久対応「Herpの日程調整ツール必須」＝構造的対策の好例。
A31: 28 | B31: ADO-28 | C31: ADO | D31: 46252 | E31: 46252 | F31: 2026 | G31: 社会保険加入手続き漏れ | H31: 業務起因_ルール不足 | I31: 1 | J31: 1名 | L31: 入退社スプシに「社保加入要否」を追加し、関数で自動表示されるようにする | M31: shuzo | N31: shuzo | O31: 46254 | P31: 46254 | Q31: 46254 | S31: =IF(AND(N31<>"",O31<>""),"○",IF(N31<>"","△","×")) -> ○ | T31: =IF(Q31<>"","○","×") -> ○ | U31: =IF(L31="","対策未記載",IF(Q31<>"","完了",IF(AND(P31<>"",P31<TODAY()),"期限超過",IF(O31="","承認日なし","対応中")))) -> 完了 | V31: 入退社・労務手続き | W31: ★事例⑥ | X31: インターンの社保加入漏れ。恒久対応「入退社スプシに社保加入要否を関数で自動表示」。シートの現物。完了2026/8/20。
A32: 29 | B32: ADO-29 | C32: ADO | D32: 46290 | E32: 46293 | F32: 2026 | G32: 給与支給漏れ | I32: 3 | J32: 1名 | K32: 個人情報にもなるため、ここでは非開示とさせてください。 | L32: 休職中などで、日割り計算をお願いする場合(前月の給与を支給していない育休、休職者)は個別で勤怠データをチェックします。 勤怠締め前にピックアップして該当者の出勤簿を確認します。 出勤簿上で有給の日数を含めた、正しい日数を確認し、 社労士に連携する勤怠データの出勤日数を修正する。(有給を取得している場合は日数が合っていない前提です。) 上記をマニュアルに記載しました。 https://docs.google.com/document/d/1NEvLHiuZVhns7vouYthe8eodSG1ruxnwNSmCbo9LqZQ/edit?tab=t.0 | M32: shuzo | N32: shuzo | O32: 46293 | P32: 46293 | Q32: 46293 | R32: 有給の全休日の支給漏れを防ぐ：出勤日数（実打刻）だけで日割りすると、夏季・冬季などの有給の全休日が支給日数から抜け落ちます。支給日数の定義（出勤日数＋有給の全休日数）を明記することで、1日分の未支給を未然に防ぎます。 | S32: =IF(AND(N32<>"",O32<>""),"○",IF(N32<>"","△","×")) -> ○ | T32: =IF(Q32<>"","○","×") -> ○ | U32: =IF(L32="","対策未記載",IF(Q32<>"","完了",IF(AND(P32<>"",P32<TODAY()),"期限超過",IF(O32="","承認日なし","対応中")))) -> 完了 | V32: 給与計算（SCSK連携） | W32: ★事例④ | X32: 休職復帰者の日割り計算ミス。恒久対応「日割り対象者の出勤簿を個別確認（マニュアル化）」。マニュアルの該当箇所と直近の適用例。原因分類が空欄。
A33: 30 | B33: ADO-30 | C33: ADO | D33: 46290 | E33: 46296 | F33: 2026 | G33: 過重支払い | H33: 業務起因_作業起因 | I33: 3 | J33: 1件 | K33: 2,970,274円 | L33: 支払いに関する AI チェックで、そもそもエラーが出てくる件数を 10 件以内にするというのを目標にする。 | M33: shuzo | N33: shuzo | O33: 46302 | P33: 46418 | S33: =IF(AND(N33<>"",O33<>""),"○",IF(N33<>"","△","×")) -> ○ | T33: =IF(Q33<>"","○","×") -> × | U33: =IF(L33="","対策未記載",IF(Q33<>"","完了",IF(AND(P33<>"",P33<TODAY()),"期限超過",IF(O33="","承認日なし","対応中")))) -> 対応中 | V33: 支払い（漏れ・過重） | W33: ★事例① | X33: オンワード 297万円の過重払い。AIチェックが検出したのに「問題なし」と判断。恒久対応「AIチェックのエラー件数を10件以内にする目標」（完了予定2027/1/31）は対策というより目標。検出→判断の記録と、資産照合の月次実施状況を確認。
A34: 31 | B34: ADO-31 | C34: ADO | D34: 46290 | E34: 46296 | F34: 2026 | G34: 支払い漏れ | H34: 業務起因_作業起因 | I34: 1 | J34: 1件 | K34: 約8,000円 | S34: =IF(AND(N34<>"",O34<>""),"○",IF(N34<>"","△","×")) -> × | T34: =IF(Q34<>"","○","×") -> × | U34: =IF(L34="","対策未記載",IF(Q34<>"","完了",IF(AND(P34<>"",P34<TODAY()),"期限超過",IF(O34="","承認日なし","対応中")))) -> 対策未記載 | V34: 支払い（漏れ・過重） | W34: 参考 | X34: 大成への支払漏れ。恒久対応策・承認すべて空欄。
A35: 32 | B35: ADO-32 | C35: ADO | D35: 46296 | E35: 46303 | F35: 2026 | G35: 有給付与の対応ミス | H35: 業務起因_ルール不足 | I35: 1 | J35: 8名 | K35: なし | L35: CSV等から一括で休暇付与を行った場合は、登録後に雇用形態（正社員・非正規）ごとに複数名を抽出し、付与日数・付与回数に重複がないか確認する。 マニュアルにも追加済です。 https://docs.google.com/spreadsheets/d/1LyRH1uTL6xVHQtA-N7jDdTWY0tFNORHzsbPYan8tSts/edit?gid=1543605334#gid=1543605334&range=331:331 | M35: shuzo | N35: shuzo | O35: 46302 | R35: 登録後に雇用形態ごとのチェックを行うことで、重複登録や登録漏れを早期に発見できると考える。今後の休暇付与時に運用し、再発がないか確認することによって未然に防ぎます。 | S35: =IF(AND(N35<>"",O35<>""),"○",IF(N35<>"","△","×")) -> ○ | T35: =IF(Q35<>"","○","×") -> × | U35: =IF(L35="","対策未記載",IF(Q35<>"","完了",IF(AND(P35<>"",P35<TODAY()),"期限超過",IF(O35="","承認日なし","対応中")))) -> 対応中 | V35: 入退社・労務手続き | W35: ★事例⑥ | X35: 有給付与の重複（8名）。恒久対応「一括登録後に雇用形態ごとの重複確認（マニュアル追加済）」。マニュアル該当箇所。承認2026/10/7、期限・完了なし。
A36: 33 | B36: ADO-33 | C36: ADO | D36: 46308 | E36: 46308 | F36: 2026 | G36: 人事共有の情報間違い | H36: 業務起因_作業起因 | I36: 1 | J36: 1件 | K36: なし | L36: 発信前のWチェックをマストにする（スクショを総務チャンネルで共有） | M36: shuzo | N36: shuzo | O36: 46309 | P36: 46309 | Q36: 46309 | S36: =IF(AND(N36<>"",O36<>""),"○",IF(N36<>"","△","×")) -> ○ | T36: =IF(Q36<>"","○","×") -> ○ | U36: =IF(L36="","対策未記載",IF(Q36<>"","完了",IF(AND(P36<>"",P36<TODAY()),"期限超過",IF(O36="","承認日なし","対応中")))) -> 完了 | V36: 個人情報・情報発信 | W36: 参考 | X36: 休職者を退職者として全社発信。恒久対応「発信前のWチェック必須」。完了2026/10/14。

Sheet 集計
A1: ① 年別×レベル別（発見年ベース）
A2: 発見年 | B2: レベル1 | C2: レベル2 | D2: レベル3 | E2: 合計
A3: 2024 | B3: =COUNTIFS('母集団_2024-2026'!$F$2:$F$36,$A3,'母集団_2024-2026'!$I$2:$I$36,"1") -> 0 | C3: =COUNTIFS('母集団_2024-2026'!$F$2:$F$36,$A3,'母集団_2024-2026'!$I$2:$I$36,"2") -> 1 | D3: =COUNTIFS('母集団_2024-2026'!$F$2:$F$36,$A3,'母集団_2024-2026'!$I$2:$I$36,"3") -> 5 | E3: =COUNTIF('母集団_2024-2026'!$F$2:$F$36,$A3) -> 6
A4: 2025 | B4: =COUNTIFS('母集団_2024-2026'!$F$2:$F$36,$A4,'母集団_2024-2026'!$I$2:$I$36,"1") -> 1 | C4: =COUNTIFS('母集団_2024-2026'!$F$2:$F$36,$A4,'母集団_2024-2026'!$I$2:$I$36,"2") -> 2 | D4: =COUNTIFS('母集団_2024-2026'!$F$2:$F$36,$A4,'母集団_2024-2026'!$I$2:$I$36,"3") -> 8 | E4: =COUNTIF('母集団_2024-2026'!$F$2:$F$36,$A4) -> 11
A5: 2026 | B5: =COUNTIFS('母集団_2024-2026'!$F$2:$F$36,$A5,'母集団_2024-2026'!$I$2:$I$36,"1") -> 5 | C5: =COUNTIFS('母集団_2024-2026'!$F$2:$F$36,$A5,'母集団_2024-2026'!$I$2:$I$36,"2") -> 2 | D5: =COUNTIFS('母集団_2024-2026'!$F$2:$F$36,$A5,'母集団_2024-2026'!$I$2:$I$36,"3") -> 11 | E5: =COUNTIF('母集団_2024-2026'!$F$2:$F$36,$A5) -> 18
A6: 合計 | B6: =SUM(B3:B5) -> 6 | C6: =SUM(C3:C5) -> 5 | D6: =SUM(D3:D5) -> 24 | E6: =SUM(E3:E5) -> 35
A7: ※2024年はADGシート2件＋ADOシート（2024/9開始）4件。2026年は10/13まで。
A9: ② 原因分類×レベル（2024-2026）
A10: 原因分類 | B10: レベル1 | C10: レベル2 | D10: レベル3 | E10: 合計
A11: 業務起因_作業起因 | B11: =COUNTIFS('母集団_2024-2026'!$H$2:$H$36,$A11,'母集団_2024-2026'!$I$2:$I$36,"1") -> 3 | C11: =COUNTIFS('母集団_2024-2026'!$H$2:$H$36,$A11,'母集団_2024-2026'!$I$2:$I$36,"2") -> 4 | D11: =COUNTIFS('母集団_2024-2026'!$H$2:$H$36,$A11,'母集団_2024-2026'!$I$2:$I$36,"3") -> 15 | E11: =COUNTIF('母集団_2024-2026'!$H$2:$H$36,$A11) -> 22
A12: 業務起因_ルール不足 | B12: =COUNTIFS('母集団_2024-2026'!$H$2:$H$36,$A12,'母集団_2024-2026'!$I$2:$I$36,"1") -> 3 | C12: =COUNTIFS('母集団_2024-2026'!$H$2:$H$36,$A12,'母集団_2024-2026'!$I$2:$I$36,"2") -> 1 | D12: =COUNTIFS('母集団_2024-2026'!$H$2:$H$36,$A12,'母集団_2024-2026'!$I$2:$I$36,"3") -> 8 | E12: =COUNTIF('母集団_2024-2026'!$H$2:$H$36,$A12) -> 12
A13: （空欄） | B13: =COUNTIFS('母集団_2024-2026'!$H$2:$H$36,"",'母集団_2024-2026'!$I$2:$I$36,"1") -> 0 | C13: =COUNTIFS('母集団_2024-2026'!$H$2:$H$36,"",'母集団_2024-2026'!$I$2:$I$36,"2") -> 0 | D13: =COUNTIFS('母集団_2024-2026'!$H$2:$H$36,"",'母集団_2024-2026'!$I$2:$I$36,"3") -> 1 | E13: =COUNTIF('母集団_2024-2026'!$H$2:$H$36,"") -> 1
A14: 合計 | B14: =SUM(B11:B13) -> 6 | C14: =SUM(C11:C13) -> 5 | D14: =SUM(D11:D13) -> 24 | E14: =SUM(E11:E13) -> 35
A17: ③ 恒久対応の記録状況
A18: 指標 | B18: 全体（件） | C18: 全体（率） | D18: レベル3（件） | E18: レベル3（率）
A19: 母集団件数 | B19: =COUNTA('母集団_2024-2026'!$B$2:$B$36) -> 35 | D19: =COUNTIF('母集団_2024-2026'!$I$2:$I$36,"3") -> 24
A20: 恒久対応策の記入 | B20: =COUNTIF('母集団_2024-2026'!$L$2:$L$36,"<>") -> 31 | C20: =B20/$B$19 -> 0.88571429 | D20: =COUNTIFS('母集団_2024-2026'!$I$2:$I$36,"3",'母集団_2024-2026'!$L$2:$L$36,"<>") -> 23 | E20: =D20/$D$19 -> 0.95833333
A21: 恒久対応承認者の記入 | B21: =COUNTIF('母集団_2024-2026'!$N$2:$N$36,"<>") -> 27 | C21: =B21/$B$19 -> 0.77142857 | D21: =COUNTIFS('母集団_2024-2026'!$I$2:$I$36,"3",'母集団_2024-2026'!$N$2:$N$36,"<>") -> 19 | E21: =D21/$D$19 -> 0.79166667
A22: 恒久対応承認日の記入 | B22: =COUNTIF('母集団_2024-2026'!$O$2:$O$36,"<>") -> 24 | C22: =B22/$B$19 -> 0.68571429 | D22: =COUNTIFS('母集団_2024-2026'!$I$2:$I$36,"3",'母集団_2024-2026'!$O$2:$O$36,"<>") -> 18 | E22: =D22/$D$19 -> 0.75
A23: 完了予定日の設定 | B23: =COUNTIF('母集団_2024-2026'!$P$2:$P$36,"<>") -> 22 | C23: =B23/$B$19 -> 0.62857143 | D23: =COUNTIFS('母集団_2024-2026'!$I$2:$I$36,"3",'母集団_2024-2026'!$P$2:$P$36,"<>") -> 17 | E23: =D23/$D$19 -> 0.70833333
A24: 対応完了日の記入 | B24: =COUNTIF('母集団_2024-2026'!$Q$2:$Q$36,"<>") -> 13 | C24: =B24/$B$19 -> 0.37142857 | D24: =COUNTIFS('母集団_2024-2026'!$I$2:$I$36,"3",'母集団_2024-2026'!$Q$2:$Q$36,"<>") -> 9 | E24: =D24/$D$19 -> 0.375
A25: 有効性の記入 | B25: =COUNTIF('母集団_2024-2026'!$R$2:$R$36,"<>") -> 11 | C25: =B25/$B$19 -> 0.31428571 | D25: =COUNTIFS('母集団_2024-2026'!$I$2:$I$36,"3",'母集団_2024-2026'!$R$2:$R$36,"<>") -> 8 | E25: =D25/$D$19 -> 0.33333333
A26: 参考：SCMG（32件）は恒久対応策62.5%／承認日15.6%／完了日3.1%、GRG（159件）は恒久対応策93.1%／完了日33.3%。有効性はいずれも0%。
A28: ④ ステータス内訳（レベル3）
A29: ステータス | B29: 件数
A30: 対策未記載 | B30: =COUNTIFS('母集団_2024-2026'!$I$2:$I$36,"3",'母集団_2024-2026'!$U$2:$U$36,$A30) -> 1
A31: 承認日なし | B31: =COUNTIFS('母集団_2024-2026'!$I$2:$I$36,"3",'母集団_2024-2026'!$U$2:$U$36,$A31) -> 5
A32: 期限超過 | B32: =COUNTIFS('母集団_2024-2026'!$I$2:$I$36,"3",'母集団_2024-2026'!$U$2:$U$36,$A32) -> 7
A33: 対応中 | B33: =COUNTIFS('母集団_2024-2026'!$I$2:$I$36,"3",'母集団_2024-2026'!$U$2:$U$36,$A33) -> 2
A34: 完了 | B34: =COUNTIFS('母集団_2024-2026'!$I$2:$I$36,"3",'母集団_2024-2026'!$U$2:$U$36,$A34) -> 9
A36: ⑤ 会計影響（過重払い・支払漏れの金額が判明している主な案件）
A37: ユニークID | B37: 案件 | C37: 金額（円）
A38: ADO-1 | B38: 非正規社員給与の支払申請漏れ | C38: 5292692
A39: ADO-5 | B39: 振込過重払い | C39: 831449
A40: ADO-8 | B40: 振込漏れ | C40: 804100
A41: ADO-17 | B41: 日本郵便 支払漏れ | C41: 2237268
A42: ADO-19 | B42: ヤーマン 過重払い | C42: 1532540
A43: ADO-21 | B43: クラスメソッド 過重払い | C43: 956111
A44: ADO-30 | B44: オンワード 過重払い | C44: 2970274
B45: 合計 | C45: =SUM(C38:C44) -> 14624434
...

Sheet 再発パターン
A1: 再発パターン | B1: 該当インシデント（ユニークID／発見日／レベル／金額） | C1: 掲げられた恒久対応策の変遷 | D1: 監査での論点
A2: 取引先・従業員への支払い漏れ／過重払い／誤送金 | B2: ADG-2 2021/2 Lv2／ADG-9 2022/5 Lv2／ADG-15 2023/7 Lv3 150万／ADG-17 2023/12 Lv2／ADG-18 2024/1 Lv3 55万／ADO-1 2024/9 Lv3 529万／ADO-5 2025/2 Lv3 83万／ADO-6 2025/2 Lv2／ADO-8 2025/6 Lv3 80万／ADO-9 2025/8 Lv1／ADO-13 2025/9 Lv3／ADO-16 2026/3 Lv2 8万／ADO-17 2026/4 Lv3 224万／ADO-19 2026/5 Lv3 153万／ADO-21 2026/6 Lv3 96万／ADO-30 2026/10 Lv3 297万／ADO-31 2026/10 Lv1 | C2: 2021〜2025：チェックリスト・Wチェック・振込前確認の徹底 ／ 2026/5：AIチェック完成までトリプルチェック ／ 2026/6：100万円以上の差異を自動検知、AIに重複検知を追加 ／ 2026/10：AIチェックのエラー件数10件以内を目標 | D2: 2026年だけで6件・計約680万円が一時的に社外へ。対策は「人の確認を増やす」から「AIチェック」に移ったが、#30ではAIが検出しても人が見逃した。AIチェックの検出→判断→承認の記録と、資産照合・件数チェックの月次実施を現物で確認。ADO②No.15（現預金）に直結。
A3: 給与・交通費の計算ミス（社労士／SCSK連携） | B3: ADG-3 2021/3／ADG-5,6,7 2021/11／ADG-8 2022/2／ADG-12 2022/12／ADO-7 2025/3 Lv3／ADO-15 2025/11 Lv3／ADO-18 2026/4 Lv3／ADO-20 2026/5 Lv3／ADO-22 2026/6 Lv3／ADO-29 2026/9 Lv3 | C3: 2021〜2022：社労士連携シートのWチェック ／ 2025：給与台帳と支払金額の突合 ／ 2026：関数修正・SmartHR経由に統一・イレギュラーチェックリスト・日割りマニュアル | D3: 外注先（SCSK）への連携シートが起点のミスが5年間続く。2026年は対策が「チェックリスト化・関数化」に進んだので、その現物と毎月の実施記録を確認。ADO②No.20（労務）に関連。
A4: 資金繰り・金融機関との約束 | B4: ADG-14 2023/6 Lv3（給与支払遅延未遂）／ADG-19 2024/5 Lv3（同じ事象が再発）／ADO-23 2026/4 Lv3（銀行遵守事項違反） | C4: 2023：月次決算後の資金移動＋支払時の残高付箋 ／ 2024：「運用の問題」としてカレンダーで毎月資金移動 ／ 2026：金融機関契約の全件洗い出し、月2回の資金繰り確認で遵守事項を確認 | D4: 2023→2024は恒久対応が運用で守られず再発。2026は財務制限条項の未管理という上場会社として重い事象。遵守事項一覧の現物、月2回の確認記録、取締役会・監査役への報告。ADO②No.15・17に直結。
A5: 契約更新・稟議（事後稟議） | B5: ADG-16 2023/11 Lv3（事後稟議）／ADO-11 2025/8 Lv3（インターン契約更新漏れ）／ADO-14 2025/10 Lv3（スタイリスト8名の契約更新漏れ）／ADO-25 2026/7 Lv3（ジョブカン承認前に契約締結） | C5: 2023：契約Slackをリーダーが月次確認 ／ 2025：入退社チェックリストへの転記、JOBCAN最終版添付の徹底・電子契約の台帳網羅性の月次確認・Botアラート再構築 ／ 2026：「運用徹底」のみ（恒久対応策空欄） | D5: ADO自身が全社に求める「事後稟議禁止」「契約一覧表での期限管理」（ADO②No.14・28）が、自部門で破られている。台帳の月次網羅性確認とBotの実装状況を現物で確認。#25は起票者が倉石のため森本が確認。
A6: 開示・税務の手続きミス | B6: ADO-10 2025/8 Lv3（適時開示漏れ・東証指摘）／ADO-12 2025/9 Lv2（源泉所得税の申告未受理・延滞税）／ADO-24 2026/7 Lv3（Meta広告費の消費税区分誤り）／ADG-11 2022/11 Lv2（事業所税の申告誤り） | C6: 2022：顧問税理士チェック・マニュアル ／ 2025：取締役会2営業日前の確認時間、生成AIで開示要否確認 ／ #12は恒久対応策なし ／ 2026：AIチェックに税区分・インボイス整合性を追加 | D6: 上場会社の開示・税務は1件でも影響が大きい。#10の確認時間の運用記録、#12の出金記録照合、#24のAIチェック実装（完了予定2026/7/31超過）。ADO②No.18（会計方針）に関連。
A7: 入退社・労務手続き（台帳・WF） | B7: ADO-11 2025/8（契約更新）／ADO-26 2026/8 Lv2（住民税異動届）／ADO-28 2026/8 Lv1（社保加入漏れ）／ADO-32 2026/10 Lv1（有給付与重複） | C7: 入退社チェックリスト・WFに項目追加、入退社スプシに関数で自動表示、マニュアル追加 | D7: 対策が「チェックリスト・WF・関数」という構造的な形になっている好例。実際に項目が追加され、直近の入退社で使われたかを確認。
A8: 個人情報・情報発信 | B8: ADO-4 2024/12 Lv3（候補者名の誤記）／ADO-33 2026/10 Lv1（休職者を退職者として全社発信）／ADO-2 2024/11 Lv3（モバイルSuica個人利用） | C8: フルネーム確認の徹底 ／ 発信前のWチェック必須（スクショ共有） ／ 2台持ちルール | D8: いずれも人依存の対策。ADO②No.9（個人情報保護）で「他部署への啓蒙」を掲げる部門として、自部門の個人情報取扱いを確認。

Sheet 事例6件_調書
A1: 事例 | B1: インシデント | C1: テスト観点 | D1: 確認内容（事前準備した論点） | E1: 確認した証憑（当日記入） | F1: 結果(○△×－) | G1: 発見事項（当日記入）
A2: ① | B2: #17 日本郵便 支払漏れ 224万円（2026/4 Lv3） #19 ヤーマン 過重払い 153万円（2026/5 Lv3） #21 クラスメソッド 過重払い 96万円（2026/6 Lv3） #30 オンワード 過重払い 297万円（2026/10 Lv3） | C2: G1 承認 | D2: 承認者shuzo・承認日あり（#17 4/1、#19 5/27、#21 6/16、#30 10/7）。レベル3としての社長承認の形跡（役員会確認欄は全件空欄）。
C3: G2 実装・運用 | D3: 件数チェック（#17）、Wチェック＋トリプルチェック（#19）、100万円差異の自動Slack通知と重複検知（#21）、AIチェック運用（#30）の現物。AIチェックの検出結果と「問題なし」と判断した記録。
C4: G3 有効性・再発 | D4: #19完了（5/27）の直後に#21（6/16）、#30（10/1）と同型が再発。対策が人の確認の積み増しに留まっていないか。資産照合（月中）の実施記録。
C5: G4 完了確認 | D5: #30は完了予定2027/1/31で対応中。#17は完了日なし。
C6: 総合評価 | D6: ○有効／△一部不備／×不備／－対応中 → 結論（事実→影響→根本原因）と改善の要否
A8: ② | B8: ADG-19 給与支払遅延未遂（2024/5 Lv3・2023/6の再発） #23 銀行との契約上の遵守事項違反（2026/4発生・6/18発見 Lv3） | C8: G1 承認 | D8: ADG-19は承認ash 2024/5/27。#23は承認shuzo 2026/6/19。財務制限条項違反としての取締役会・監査役への報告有無。
C9: G2 実装・運用 | D9: 月次資金移動のカレンダー設定と実施記録。金融機関契約の遵守事項を洗い出した一覧の現物と、月2回の資金繰り確認での確認記録。
C10: G3 有効性・再発 | D10: 2023→2024で同じ事象が再発した後、2026に資金繰り起因の別事象。資金繰り管理が属人化していないか。
C11: G4 完了確認 | D11: #23は完了予定2026/6/19に対し完了日なし。
C12: 総合評価 | D12: ○有効／△一部不備／×不備／－対応中 → 結論（事実→影響→根本原因）と改善の要否
A14: ③ | B14: #14 スタイリスト8名の契約更新漏れ（2025/10 Lv3） #25 ジョブカン承認前に契約締結（2026/7 Lv3） | C14: G1 承認 | D14: #14は承認者shuzoのみで承認日なし。#25は承認者・承認日とも空欄。
C15: G2 実装・運用 | D15: JOBCANへの最終版添付、電子契約の台帳網羅性の月次確認フロー、契約書台帳の区分とBotアラートの現物（別シートNo14の対策①〜③）。
C16: G3 有効性・再発 | D16: 2023（ADG-16）以降3回目の契約・稟議事象。ADO②No.14・28の自己評価との整合。
C17: G4 完了確認 | D17: #14・#25とも完了予定・完了日なし。#25は恒久対応策自体が空欄。
C18: 総合評価 | D18: ○有効／△一部不備／×不備／－対応中 → 結論（事実→影響→根本原因）と改善の要否
A20: ④ | B20: #7 給与過小（2025/3 Lv3） #20 早出残業手当の誤支給（2026/5 Lv3） #22 控除ミス（2026/6 Lv3） #29 休職復帰者の給与支給漏れ（2026/9 Lv3） | C20: G1 承認 | D20: いずれも承認者shuzo・承認日あり。#22・#29は完了日あり、#7・#20は完了予定日を過ぎて完了日なし。
C21: G2 実装・運用 | D21: 給与台帳と支払金額の突合（#7）、修正後のSCSK連携シート（#20）、イレギュラー支払チェックリスト（#22）、日割りマニュアル（#29）の現物と直近月の実施記録。
C22: G3 有効性・再発 | D22: #15・#18（交通費）を含め2025〜2026で6件。チェックリスト化後の再発有無。
C23: G4 完了確認 | D23: 有効性欄の記述が「効くはず」という見込みで、事後検証になっているか。
C24: 総合評価 | D24: ○有効／△一部不備／×不備／－対応中 → 結論（事実→影響→根本原因）と改善の要否
A26: ⑤ | B26: #10 適時開示漏れ（2025/8 Lv3） #12 源泉所得税の申告未受理（2025/9 Lv2） #24 Meta広告費の消費税区分誤り（2026/7 Lv3） | C26: G1 承認 | D26: #10・#24は承認shuzo。#12は承認者・承認日とも空欄。
C27: G2 実装・運用 | D27: 取締役会2営業日前の確認時間のカレンダー設定と直近の確認記録（#10）、e-tax申告後の出金記録照合（#12）、AIチェックの税区分項目（#24）。
C28: G3 有効性・再発 | D28: 上場会社の開示・税務手続きの再発有無。#12のような「恒久対応策なし」で放置されていないか。
C29: G4 完了確認 | D29: #24は完了予定2026/7/31超過。#12は恒久対応策・期限すべて空欄。
C30: 総合評価 | D30: ○有効／△一部不備／×不備／－対応中 → 結論（事実→影響→根本原因）と改善の要否
A32: ⑥ | B32: #11 インターン契約更新漏れ（2025/8 Lv3） #26 住民税異動届（2026/8 Lv2） #28 社保加入漏れ（2026/8 Lv1） #32 有給付与重複（2026/10 Lv1） | C32: G1 承認 | D32: #28は承認日・完了日あり。#11は完了予定2025/8/20に対し完了日なし。#26は承認日なし、#32は期限・完了日なし。
C33: G2 実装・運用 | D33: 入退社チェックリストの追加項目、退職WF・産育休WFの1/1時点住所欄、入退社スプシの社保加入要否の関数、休暇付与マニュアルの現物。
C34: G3 有効性・再発 | D34: 直近の入退社で実際に使われたか（記入済みのチェックリスト1件）。
C35: G4 完了確認 | D35: #26・#32の期限設定とクローズ。
C36: 総合評価 | D36: ○有効／△一部不備／×不備／－対応中 → 結論（事実→影響→根本原因）と改善の要否

Sheet 事前依頼リスト
A1: # | B1: 関連事例 | C1: 準備いただきたい現物（既存物でOK・新規作成不要） | D1: 想定の形 | E1: 備考
A2: 1 | B2: ① | C2: 支払いAIチェックの直近の実行結果（検出一覧）と、検出後に「問題なし」と判断した記録（#30） | D2: 画面共有・Slack | E2: AIチェックの運用実態
A3: 2 | B3: ① | C3: 仮申請と差替後の金額差100万円以上を自動検知するSlack通知の設定と通知例（#21） | D3: Slack・設定画面 | E3: 構造的対策の実装確認
A4: 3 | B4: ① | C4: 支払管理レポートと支払依頼の件数チェック、資産照合（月中）の直近月の記録（#17・#30） | D4: スプレッドシート | E4: 月次統制の実施記録
A5: 4 | B5: ② | C5: 金融機関との契約上の遵守事項を洗い出した一覧と、月2回の資金繰り確認での確認記録（#23） | D5: スプレッドシート・議事メモ | E5: 財務制限条項の管理
A6: 5 | B6: ② | C6: 毎月の資金移動のカレンダー設定（ADG-19） | D6: カレンダー画面 | E6: 2023→2024再発案件の対策継続
A7: 6 | B7: ③ | C7: 契約書台帳（区分・満了日・Botアラート設定）と、電子契約の台帳網羅性を月次確認した記録（#14） | D7: スプレッドシート・Slack Bot | E7: 契約更新漏れの対策
A8: 7 | B8: ③ | C8: ジョブカン承認と契約締結の順序を担保する運用（#25）。直近の契約3件の承認日と締結日 | D8: ジョブカン画面 | E8: 事後稟議の再発防止
A9: 8 | B9: ④ | C9: イレギュラー支払チェックリスト（#22）と直近月の記入済み分、給与台帳と支払金額の突合記録（#7） | D9: スプレッドシート | E9: 給与計算の月次統制
A10: 9 | B10: ④ | C10: 修正後のSCSK連携シート（みなし残業時間の別列化 #20）、日割り計算マニュアル（#29） | D10: スプレッドシート・ドキュメント | E10: 対策の現物
A11: 10 | B11: ⑤ | C11: 取締役会2営業日前の適時開示確認のカレンダー設定と直近の確認記録（#10）、AIチェックの税区分・インボイス項目（#24） | D11: カレンダー・画面 | E11: 開示・税務の統制
A12: 11 | B12: ⑤ | C12: 源泉所得税のe-tax申告後に出金記録（毎月2本）を照合する運用の有無（#12） | D12: 口頭でも可 | E12: 恒久対応策が空欄の案件
A13: 12 | B13: ⑥ | C13: 入退社チェックリスト・退職WF・入退社スプシの追加項目（#11・#26・#28）と、直近の入退社で記入済みのもの1件 | D13: スプレッドシート・WF画面 | E13: 対策の運用実績
... A16: 15 | B16: － | C16: 2027年6月期 内部監査シート ADO②タブの「（前回）監査結果」列の更新（2024/11結果への差替え） | D16: スプレッドシート | E16: 監査前の準備事項

Sheet ADO②との対応
A1: ADO② No | B1: 項目 | C1: 質問内容（要約） | D1: 前回（2024/11）の結果 | E1: 関連インシデント | F1: 今回の確認観点
A2: 3 | B2: 規程管理 | C2: 組織・業務変更に合わせた規程改訂 | D2: △ 組織体制変更時の対応が一部未了 | E2: － | F2: 未了だった規程の改訂完了有無。2026年の組織変更（Log_div等）の反映。
A3: 9 | B3: 個人情報保護 | C3: プライバシーポリシーに則った取扱い | D3: ○ 他部署への啓蒙活動を行ってほしい | E3: ADO-4, ADO-33, SCMG-75 | F3: 自部門の個人情報取扱い（候補者情報・人事情報の発信）のWチェック運用。
A4: 11 | B4: 情報管理 | C4: アクセス制限・退職時のアカウント管理 | D4: ○ 退職者のDOMOパスワード変更までの日数を決めた方がよい | E4: SCMG-79（倉庫共有アカウント） | F4: 日数ルールの設定有無。各部門の共有アカウントの棚卸し。
A5: 14 | B5: 決裁ルート | C5: 稟議・決裁基準表に基づくWF承認 | D5: ○ 管理されている | E5: ADO-25, SCMG-54, SCMG-64, GRG事後稟議 | F5: ADO自身で事後稟議が発生。全社の事後稟議件数の把握と再発防止策。
A6: 15 | B6: 現預金 | C6: 帳簿残高と銀行残高の照合 | D6: ○ 実施している | E6: ADO-17, 19, 21, 30（過重払い・支払漏れ） | F6: 照合で過重払いが検知されたか。資産照合の月次実施記録。
A7: 16 | B7: 小口現金 | C7: 小口現金の処理 | D7: ○ エコセールの現預金不一致を精査中 | E7: － | F7: エコセール現預金不一致の精査結果と再発防止。
A8: 17 | B8: 借入金 | C8: 返済予定表どおりの返済 | D8: ○ 行われている | E8: ADO-23（銀行遵守事項違反） | F8: 財務制限条項の一覧管理と月次確認。取締役会・監査役への報告。
A9: 18 | B9: 会計方針 | C9: 重要な会計方針の変更 | D9: ○ 変更はない | E9: ADO-24（消費税区分） | F9: 取引形態変更時の税区分見直しルール。AIチェックへの反映。
A10: 20 | B10: 労務 | C10: 三六協定違反等 | D10: ○ 発生していない | E10: GRG監査で45時間超4回のメンバーあり | F10: 全社の残業時間モニタリングと特別条項の運用。
A11: 21 | B11: 労務 | C11: 服務不安定な社員の管理 | D11: ○ 基準は明確に設定していない | E11: ADO-29（休職復帰者） | F11: 休職・復帰時の給与・勤怠処理の手順（マニュアル化されたか）。
A12: 23 | B12: 安全衛生 | C12: 衛生委員会の定期開催 | D12: △ 議事録作成が後手 | E12: － | F12: 議事録の適時作成の仕組み化。開催実績。
... A14: 28 | B14: 契約 | C14: 契約一覧表による期限管理 | D14: ○ 定期的に確認 | E14: ADO-11, ADO-14（契約更新漏れ） | F14: 契約書台帳の網羅性（電子契約）とBotアラートの再構築状況。

Sheet 全件_2020-2026
A1: No | B1: ユニークID | C1: 出典 | D1: 発生日 | E1: 発見日 | F1: 課題タイトル | G1: 原因分類 | H1: レベル | I1: 影響範囲 | J1: 会計影響 | K1: 恒久対応策（抜粋） | L1: 恒久対応承認者 | M1: 恒久対応承認日 | N1: 完了予定日 | O1: 対応完了日 | P1: 有効性（抜粋）
A2: 1 | B2: ADG-1 | C2: ADG | D2: 44012 | E2: 44210 | F2: 2020年6月期末のFittingの商品評価損ずれ | G2: 無 | H2: 3 | I2: 決算数値への影響なし | K2: 原因がエクセルを使用したマニュアル計算の誤りであり、決算業務に関するチェック体制が不十分であったと考えられるため、同様の原因による誤りについて確認する必要があると考えます。 こちらはチェックリストを作成しましたので、別紙でご説明させていただきます。 | L2: ash | M2: 44460 | N2: 44460 | O2: 44460
A3: 2 | B3: ADG-2 | C3: ADG | D3: 44239 | E3: 44239 | F3: 支払い遅延 | G3: 無 | H3: 2 | I3: 決算数値への影響なし | K3: 前払いについてはスプレッドシートを使用して別途管理を実施する。 （運用検討中） | L3: mash | M3: 44581 | N3: 44581 | O3: 44581
A4: 3 | B4: ADG-3 | C4: ADG | D4: 44265 | E4: 44265 | F4: 給与間違い | G4: 無 | H4: 2 | I4: 対象者１名 決算数値への影響あり | K4: 正社員雇用契約承認申請を申請する際、内定通知書も一緒に提出する。 | L4: mash | M4: 44270 | N4: 44270 | O4: 44270
A5: 4 | B5: ADG-4 | C5: ADG | D5: 44335 | E5: 44341 | F5: 郵送物のあて先と内容物の相違 | G5: 無 | H5: 1 | I5: 郵送完了前に取戻しを行ったため、実影響はなし | K5: 発送業務の操作担当者のほか、チェック者を立ててダブルチェックを実施する | L5: shuzo
A6: 5 | B6: ADG-5 | C6: ADG | D6: 44515 | E6: 44515 | F6: 給与（交通費）支給漏れ | G6: 無 | H6: 1 | I6: 対象者1名 | J6: 12390.0 | K6: イレギュラー事項が発生した場合、社労士連携シートへその場で記入する イレギュラー対応が発生することを事前に本人へ連絡をする際に、必ずccにkurachanを入れる | L6: morimo | M6: 44516 | N6: 44545 | O6: 44545
A7: 6 | B7: ADG-6 | C7: ADG | D7: 44515 | E7: 44515 | F7: 給与（交通費）支給間違い | G7: 無 | H7: 1 | I7: 対象者1名 | J7: -8704.0 | K7: 入社時もしくは登録情報変更時に、SmartHRの情報を転記する際、必ずkurachanにWチェックをしていただく | L7: morimo | M7: 44516 | N7: 44545 | O7: 44545
A8: 7 | B8: ADG-7 | C8: ADG | D8: 44515 | E8: 44515 | F8: 給与（交通費）支給漏れ | G8: 無 | H8: 1 | I8: 対象者1名 | J8: 10970.0 | K8: PSGからのリモートメンバー一覧を、給与計算前にPSGに最終チェックをしていただく ⇒社労士連携シートに転記した情報をkurachanにＷチェックしていただく | L8: morimo | M8: 44516 | N8: 44545 | O8: 44545
A9: 8 | B9: ADG-8 | C9: ADG | D9: 44575 | E9: 44607 | F9: 1月給与のスタイリスト報酬の過払い（対象者10名） | G9: 無 | H9: 2 | I9: 対象者10名 | J9: 0.0 | K9: ①社労士様へ計算依頼をする前にデータをPSG側に確認していただき認識を合わせる （②報酬額の内訳をPSGより共有いただき違和感ないかをADGでも見る） | L9: morimo | M9: 44614 | N9: 44696 | O9: 44696
A10: 9 | B10: ADG-9 | C10: ADG | D10: 44696 | E10: 44706 | F10: 経費の振込漏れ | G10: 無 | H10: 2 | I10: 対象者4名 | J10: 0.0 | K10: 支払対象リストの絞り込みを正しい方法に直したので今後は起きない想定。 一方、口座情報及び、取引先情報が正しく入力できているか、振込前にチェックする体制に変更を行った。 | L10: morimo | M10: 44706 | N10: 44706 | O10: 44706
A11: 10 | B11: ADG-10 | C11: ADG | D11: 44659 | E11: 44817 | F11: シェア割ロジックにおける景表法一部抵触の可能性 | G11: 無し | H11: 3 | I11: 常に変動しており、現状把握困難。 | J11: 0.0 | K11: 法務相談の種類により以下のように体制を変更する。 ・単独で動いている外部弁護士には、契約書レビュー等、アウトプットが明確なものを依頼する。 ・法律的な適正性等については弁護士のダブルチェックが受けられる外部委託先に依頼する。 ・重要度（リスク）が高いにも関わらず期日感等で、急ぎの相談の場合はADGが必ず関与する。 | L11: ash | M11: 44858 | N11: 44858 | O11: 44858
A12: 11 | B12: ADG-11 | C12: ADG | D12: 44799 | E12: 44866 | F12: 事業所税の従業員割に係る申告額に誤りがあった | G12: 無し | H12: 2 | J12: 250,000円弱（延滞金含む） | K12: 顧問税理士によるチェックを実施する 各種数字の算出根拠についてマニュアルを作成する | L12: shuzo | M12: 44879
A13: 12 | B13: ADG-12 | C13: ADG | D13: 44890 | E13: 44921 | F13: 給与額のミス | G13: 無し | H13: 1 | I13: 11月25日支給 1名 12月25日支給 1名 | J13: 11月25日支給 5,000円 12月25日支給 5,000円 | K13: 入社メンバーがいた場合にWチェックを行う ┗原本と社労士連携シートの金額を照らし合わせる | L13: shuzo | M13: 44946 | N13: 44951 | O13: 44951
A14: 13 | B14: ADG-13 | C14: ADG | D14: 44985 | E14: 44985 | F14: 水質汚濁防止法にかかる法令違反 | G14: 無 | H14: 3 | I14: 特になし | J14: 特になし | K14: 新規事業およびそれに類するプロジェクトの際は、WBSの中に必ず「関連法令の洗い出し」をタスクとして入れるものとする。 確認先としては、GVAさんや、事業を行う場所の行政（市区町村役所）に問い合わせ。 airCloset Mallに関しては、新規商品を取り扱う際が対象となる。 取引先（仕入先）様との契約書に「当該商品を扱うにあたって関連する法令があるか？ある場合は開示してください」という内容を盛り込… | L14: ash | M14: 45085 | N14: 45089 | O14: 45089
A15: 14 | B15: ADG-14 | C15: ADG | D15: 45100 | E15: 45100 | F15: 正社員給与の支払い遅延未遂 | G15: 無し | H15: 3 | I15: 特になし | J15: 特になし | K15: 現状、以下の統制行為を実施している。 ①月次決算終了後、口座残高を確認の上資金移動の要否を経理担当が判断している。 ②支払手続実施時に、支払担当が口座残高を確認している。 今回は①で確認はしたものの月末の支払金額を読み違えていたことと、②のフローが漏れてしまっていたために発生。 今後は、原則として①時に余裕を持って資金移動を実施する。②支払手続実施時に、請求書の束と合わせて預金残高を付箋で記載して… | L15: ash | M15: 45112 | N15: 45112 | O15: 45112
A16: 15 | B16: ADG-15 | C16: ADG | D16: 45046 | E16: 45133 | F16: 支払遅延 | G16: 無し | H16: 3 | I16: 1件約150万円 | J16: 約150万円 | K16: IDチーム側で請求書到着後にもともとの見積明細と合わせて突き合わせることで、「請求書の受け取り漏れ」についても検知する。 ⇒PDGからash確認を実施予定。 | L16: ash | M16: 45160
A17: 16 | B17: ADG-16 | C17: ADG | D17: 45232 | E17: 45232 | F17: 事後稟議 | G17: 業務起因_ルール不足 | H17: 3 | I17: 特になし | J17: 特になし | K17: 契約書締結に関するSlackチャンネルをリーダーが月次で確認し、事後稟議となる可能性のある案件の有無を把握する。 | L17: ash | M17: 45236
A18: 17 | B18: ADG-17 | C18: ADG | D18: 45275 | E18: 45280 | F18: 経費振込遅延 | G18: 業務起因_作業起因 | H18: 2 | I18: 1名。5,830円。 | J18: 無し。 | K18: 今回はかなりのイレギュラー対応。支払マスターにおける従業員番号と、労務で使用する従業員番号を統一することを徹底する。 | L18: shuzo | M18: 45280 | N18: 45280 | O18: 45280
A19: 18 | B19: ADG-18 | C19: ADG | D19: 45307 | E19: 45307 | F19: 支払漏れ | G19: 業務起因_作業起因 | H19: 3 | I19: 1名 | J19: 550,000円 | K19: 15日払いの取引先に関するチェックリストが自己チェックになっているため、イレギュラーな対応を実施する場合はダブルチェックを入れていく。 | L19: ash | M19: 45307 | N19: 45307 | O19: 45307
A20: 19 | B20: ADG-19 | C20: ADG | D20: 45436 | E20: 45436 | F20: 正社員給与の支払い遅延未遂 | G20: 業務起因_ルール不足 | H20: 3 | I20: 特になし | J20: 特になし | K20: 現状、以下の統制行為を実施している。 ①月次決算終了後、口座残高を確認の上資金移動の要否を経理担当が判断している。 ②支払手続実施時に、支払担当が口座残高を確認している。支払手続実施時に、請求書の束と合わせて預金残高を付箋で記載して承認に回すことにする。 仕組みというより、運用の問題だと思いますので徹底を図るのと、カレンダーでの予定を設定し、毎月資金移動するようにします。 | L20: ash | M20: 45439 | N20: 45439 | O20: 45439
A21: 1 | B21: ADO-1 | C21: ADO | D21: 45548 | E21: 45548 | F21: 非正規社員給与支払いミス | G21: 業務起因_作業起因 | H21: 3 | I21: 29名 | J21: 5292692.0 | K21: ADO長（shuzo）の振込承認後に、担当者が金融機関のUI上で振込承認されていることを確認する | L21: 2024/09/13 | M21: 45548 | N21: 45548 | O21: 45548
A22: 2 | B22: ADO-2 | C22: ADO | D22: 確認中ですが、2022年ごろから？ | E22: 45608 | F22: モバイルSUICAが個人利用されていた | G22: 業務起因_ルール不足 | H22: 3 | I22: 1名 | J22: 確認中 | K22: 社用モバイルSuicaを利用する場合は、2台持ち（社用携帯＋個人携帯）とする ※1台の端末に複数のモバイルSuica（モバイルPASMO含む）を入れる運用はNGとする
A23: 3 | B23: ADO-3 | C23: ADO | D23: 45617 | E23: 45617 | F23: 退社時の未施錠が発生した | G23: 業務起因_作業起因 | H23: 2 | I23: なし | J23: なし
A24: 4 | B24: ADO-4 | C24: ADO | D24: 45650 | E24: 45650 | F24: 候補者送付先ミス | G24: 業務起因_作業起因 | H24: 3 | I24: 1名 | J24: なし | K24: 事象をチーム内で共有し、フルネームを確認することを徹底することを改めて確認しました。
A25: 5 | B25: ADO-5 | C25: ADO | D25: 45713 | E25: 45714 | F25: 振込過重払い | G25: 業務起因_ルール不足 | H25: 3 | I25: 3件 | J25: ￥831,449 | K25: 基本は消込後にデータ抽出する。スケジュール的に厳しい場合はデータ抽出後でもデータ上でチェックを実施する（第一チェック者がチェックしたエクセルなどを第二チェック者に共有し、ダブルチェックを行う） | L25: shuzo | M25: 45715 | N25: 45715 | O25: 45715
A26: 6 | B26: ADO-6 | C26: ADO | D26: 45713 | E26: 45714 | F26: 振込先相違 | G26: 業務起因_作業起因 | H26: 2 | I26: 2件 | J26: ￥39,600 | K26: イレギュラー支払はフロー内で行うことを徹底する。フロー外は基本的に受けない。フロー外の支払については、GMからshuzoさんへ確認依頼し振込の可否をもらう。 | L26: shuzo | M26: 45715 | N26: 45715 | O26: 45715
A27: 7 | B27: ADO-7 | C27: ADO | D27: 45741 | E27: 45741 | F27: 給与支払いミス（過小）：2025年3月分 | G27: 業務起因_ルール不足 | H27: 3 | I27: 3名 | J27: 70000.0 | K27: 給与台帳と支払金額の一致を確認し、差異原因については上長であるADO長が確認する。 | L27: shuzo | M27: 45741 | N27: 45741
A28: 8 | B28: ADO-8 | C28: ADO | D28: 45810 | E28: 45810 | F28: 振込漏れ | G28: 業務起因_作業起因 | H28: 3 | I28: 1件 | J28: 804100.0 | K28: 口座振替、となっているものについても、請求書内容を確認し、月末を経過後に引き落としされていることを確認する時間を作る。 | L28: shuzo | M28: 45810 | N28: 45810
A29: 9 | B29: ADO-9 | C29: ADO | D29: 45876 | E29: 45876 | F29: 振込漏れ | G29: 業務起因_ルール不足 | H29: 1 | I29: 1件 | J29: ￥3,795 | K29: 支払依頼の申請者が実際の業務に関与していなかったために発生している。支払依頼管理表作成時に、担当者への確認をするフローとする。 | L29: shuzo | M29: 45879 | N29: 45810
A30: 10 | B30: ADO-10 | C30: ADO | D30: 45852 | E30: 45882 | F30: 適時開示漏れ | G30: 業務起因_ルール不足 | H30: 3 | I30: 1件 | J30: なし | K30: ・取締役会の２営業日前に確認時間をスケジュール ・生成AIを用いて、適時開示が必要そうなものがないかを確認（できるかどうか含めてテスト | L30: shuzo | M30: 45883 | N30: 45883
A31: 11 | B31: ADO-11 | C31: ADO | D31: 45870 | E31: 45883 | F31: インターン契約更新漏れ | G31: 業務起因_ルール不足 | H31: 3 | I31: 1件 | J31: なし | K31: 契約社員・インターンの管理台帳への記載が漏れないように、入退社チェックリストに当該項目の転記をルール化する。 | L31: shuzo | M31: 45889 | N31: 45889
A32: 12 | B32: ADO-12 | C32: ADO | D32: 45754 | E32: 45905 | F32: 源泉所得税の申告・納付エラー | G32: 業務起因_作業起因 | H32: 2 | I32: 1件 | J32: 金額不明だが、延滞加算税が課される
A33: 13 | B33: ADO-13 | C33: ADO | D33: 45912 | E33: 45916 | F33: 口座情報登録ミス | G33: 業務起因_作業起因 | H33: 3 | I33: 対象人数：2名 件数；1件 | J33: 2262.0 | K33: ダブルチェックを徹底します。 現状は ・プリントアウトしたものにチェックして欲しい方には印をつける ・slackでお伝えし、可能な限り口頭でも伝える ・ダブルチェックを依頼するためにshuzoさんにお渡しする前にデスクに置き チェック依頼をしていました。 ーーーーーーーーーーーーーーー 今後は入口の部分であるマスター登録のチェックの強化をします。 財務以外のメンバー(経理)にも以下をチェックしても…
A34: 14 | B34: ADO-14 | C34: ADO | D34: 最初に更新できなかった日 | E34: 45957 | F34: スタイリストさん契約更新漏れ | G34: 業務起因_ルール不足 | H34: 3 | I34: スタイリスト：8人 | J34: 0.0 | K34: ①最終版をJOBCANに添付することを徹底する。現状では法務依頼は一元化されて管理されているため、チームとして結果を確認している。 ②月次で電子契約が網羅的に台帳に記載されていることを確認するフローを入れる。 ③今回のインシデントと直接は関係無いが、契約書台帳の区分を、①ひな型による契約（自動更新有り）、②ひな型による契約（自動更新無し）、③その他契約、に分けて管理し、②③は契約満了時点でBotで… | L34: shuzo
A35: 15 | B35: ADO-15 | C35: ADO | D35: 45975 | E35: 45978 | F35: 交通費連携ミス | G35: 業務起因_作業起因 | H35: 3 | I35: 1名 | J35: 7140.0 | K35: ダブルチェックの徹底 現状はkyonkyonさんのみのチェック。今後はshuzoさんにもダブルチェックを依頼します。 その際に、今後は修正一覧表に起票し、ミスが起こりやすい部分を認識することにより、さらに注意して確認をしていきます。 修正一覧表
A36: 16 | B36: ADO-16 | C36: ADO | D36: 46081 | E36: 46093 | F36: 取引先への支払い漏れ | G36: 業務起因_作業起因 | H36: 2 | J36: 83160.0 | K36: ・請求書送信先を法務のMLの設定する ・支払い依頼管理表に追記する | L36: shuzo | P36: 半期に一度の請求等でも、支払い依頼管理表に記載されているものについては請求漏れを防げており、本件についても管理表に記載があれば防げたと考えられるため。
A37: 17 | B37: ADO-17 | C37: ADO | D37: 46112 | E37: 46113 | F37: 取引先への支払い漏れ | G37: 業務起因_作業起因 | H37: 3 | I37: 1件 | J37: 2237268.0 | K37: 支払管理レポートと支払依頼の件数チェックを行う。 | L37: shuzo | M37: 46113 | P37: 支払依頼は各グループから上がってくるため、件数の誤りは発見できる。金額が合っているかは別項目でチェックを行う。
A38: 18 | B38: ADO-18 | C38: ADO | D38: 46136 | E38: 46140 | F38: 交通費連携ミス | G38: 業務起因_作業起因 | H38: 3 | I38: 対象人数：1名 | J38: 6350.0 | K38: 今後はすべてSmartHR経由で交通費変更申請をお願いする。 今回のような料金改定により、大人数の変更が発生した際は必ず全員分をまとめて起票する。 | L38: shuzo | M38: 46142 | N38: 46142 | O38: 46142
A39: 19 | B39: ADO-19 | C39: ADO | D39: 46169 | E39: 46169 | F39: 取引先への過重支払 | G39: 業務起因_作業起因 | H39: 3 | I39: 1件 | J39: 1,532,540 円 | K39: ・最終版の請求書と支払依頼書のWチェックを行う。 ・AIチェックを進めるが、それが完成するまではshuzoがトリプルチェックを実施する。 | L39: shuzo | M39: 46169 | N39: 46169 | O39: 46169 | P39: 修正したあとの支払依頼もWチェックを行うことにより、再発の防止が見込める。AIチェックについても今後進めていき、より精度上げる。
A40: 20 | B40: ADO-20 | C40: ADO | D40: 46137 | E40: 46169 | F40: 早出残業手当支払いミス | G40: 業務起因_作業起因 | H40: 3 | I40: 対象人数：2名 うち1名については2ヶ月分の修正が必要であったところ、1名分しか修正できていなかったので追加で対応いたし… | J40: 37,423円→ | K40: ・みなし残業時間を関数に組み込むのではなく、別の列に時間数を入力しておき、関数がその列の値を参照する形式に修正する ・関数に誤りがないかをチェックする | L40: shuzo | M40: 46175 | N40: 46176 | P40: みなし残業時間が45時間以外のメンバーはほぼいないので、これでチェックできると考えております。
...
